/mnt/hwfile/huqinghao/miniconda3/bin/python
2024-05-15 21:47:25,466 - INFO - Note: detected 128 virtual cores but NumExpr set to maximum of 64, check "NUMEXPR_MAX_THREADS" environment variable.
2024-05-15 21:47:25,466 - INFO - Note: NumExpr detected 128 cores but "NUMEXPR_MAX_THREADS" not set, so enforcing safe limit of 8.
2024-05-15 21:47:25,466 - INFO - NumExpr defaulting to 8 threads.
2024-05-15 21:47:26,893	INFO scripts.py:1182 -- Did not find any active Ray processes.

==========
== CUDA ==
==========

CUDA Version 12.1.0

Container image Copyright (c) 2016-2023, NVIDIA CORPORATION & AFFILIATES. All rights reserved.

This container image and its contents are governed by the NVIDIA Deep Learning Container License.
By pulling and using the container, you accept the terms and conditions of this license:
https://developer.nvidia.com/ngc/nvidia-deep-learning-container-license

A copy of this license is made available in this container at /NGC-DL-CONTAINER-LICENSE for your convenience.

*************************
** DEPRECATION NOTICE! **
*************************
THIS IMAGE IS DEPRECATED and is scheduled for DELETION.
    https://gitlab.com/nvidia/container-images/cuda/blob/master/doc/support-policy.md

Waiting for 10 secs for the system to be ready: HTTPConnectionPool(host='localhost', port=8000): Max retries exceeded with url: /sysinfo (Caused by NewConnectionError('<urllib3.connection.HTTPConnection object at 0x7f5adc668730>: Failed to establish a new connection: [Errno 111] Connection refused'))
Waiting for 10 secs for the system to be ready: HTTPConnectionPool(host='localhost', port=8000): Max retries exceeded with url: /sysinfo (Caused by NewConnectionError('<urllib3.connection.HTTPConnection object at 0x7f5adc669450>: Failed to establish a new connection: [Errno 111] Connection refused'))
INFO 05-15 21:47:41 api_server.py:191] vLLM API server version 0.3.3
INFO 05-15 21:47:41 api_server.py:192] args: Namespace(host=None, port=8000, uvicorn_log_level='info', allow_credentials=False, allowed_origins=['*'], allowed_methods=['*'], allowed_headers=['*'], api_key=None, served_model_name=None, lora_modules=[], delta_modules=[Delta(name='delta-1', local_path='/vllm/.idea/models/13b/lmsys.vicuna-13b-v1.5.4b75s128g-1'), Delta(name='delta-2', local_path='/vllm/.idea/models/13b/lmsys.vicuna-13b-v1.5.4b75s128g-2'), Delta(name='delta-3', local_path='/vllm/.idea/models/13b/lmsys.vicuna-13b-v1.5.4b75s128g-3'), Delta(name='delta-4', local_path='/vllm/.idea/models/13b/lmsys.vicuna-13b-v1.5.4b75s128g-4'), Delta(name='delta-5', local_path='/vllm/.idea/models/13b/lmsys.vicuna-13b-v1.5.4b75s128g-5'), Delta(name='delta-6', local_path='/vllm/.idea/models/13b/lmsys.vicuna-13b-v1.5.4b75s128g-6'), Delta(name='delta-7', local_path='/vllm/.idea/models/13b/lmsys.vicuna-13b-v1.5.4b75s128g-7'), Delta(name='delta-8', local_path='/vllm/.idea/models/13b/lmsys.vicuna-13b-v1.5.4b75s128g-8'), Delta(name='delta-9', local_path='/vllm/.idea/models/13b/lmsys.vicuna-13b-v1.5.4b75s128g-9'), Delta(name='delta-10', local_path='/vllm/.idea/models/13b/lmsys.vicuna-13b-v1.5.4b75s128g-10'), Delta(name='delta-11', local_path='/vllm/.idea/models/13b/lmsys.vicuna-13b-v1.5.4b75s128g-11'), Delta(name='delta-12', local_path='/vllm/.idea/models/13b/lmsys.vicuna-13b-v1.5.4b75s128g-12'), Delta(name='delta-13', local_path='/vllm/.idea/models/13b/lmsys.vicuna-13b-v1.5.4b75s128g-13'), Delta(name='delta-14', local_path='/vllm/.idea/models/13b/lmsys.vicuna-13b-v1.5.4b75s128g-14'), Delta(name='delta-15', local_path='/vllm/.idea/models/13b/lmsys.vicuna-13b-v1.5.4b75s128g-15'), Delta(name='delta-16', local_path='/vllm/.idea/models/13b/lmsys.vicuna-13b-v1.5.4b75s128g-16')], swap_modules=[], chat_template=None, response_role='assistant', ssl_keyfile=None, ssl_certfile=None, ssl_ca_certs=None, ssl_cert_reqs=0, root_path=None, middleware=[], model='/vllm/.idea/full_models/Llama-2-13b-hf', tokenizer=None, revision=None, code_revision=None, tokenizer_revision=None, tokenizer_mode='auto', trust_remote_code=False, download_dir=None, load_format='auto', dtype='auto', kv_cache_dtype='auto', max_model_len=None, worker_use_ray=False, pipeline_parallel_size=1, tensor_parallel_size=4, max_parallel_loading_workers=None, ray_workers_use_nsight=False, block_size=16, enable_prefix_caching=False, seed=0, swap_space=4, gpu_memory_utilization=0.85, max_num_batched_tokens=None, max_num_seqs=256, max_logprobs=5, disable_log_stats=False, quantization=None, enforce_eager=True, max_context_len_to_capture=8192, disable_custom_all_reduce=False, tokenizer_pool_size=0, tokenizer_pool_type='ray', tokenizer_pool_extra_config=None, enable_lora=False, max_loras=1, max_lora_rank=64, lora_extra_vocab_size=256, lora_dtype='auto', max_cpu_loras=32, enable_delta=True, max_deltas=16, max_cpu_deltas=32, max_delta_bitwidth=4, device='auto', image_input_type=None, image_token_id=None, image_input_shape=None, image_feature_size=None, scheduler_delay_factor=0.0, enable_prefetch=False, scheduler_policy='fcfs', max_swap_slots=1, max_cpu_models=4, enable_swap=False, engine_use_ray=False, disable_log_requests=True, max_log_len=None)
2024-05-15 21:47:44,662	INFO worker.py:1749 -- Started a local Ray instance.
Waiting for 10 secs for the system to be ready: HTTPConnectionPool(host='localhost', port=8000): Max retries exceeded with url: /sysinfo (Caused by NewConnectionError('<urllib3.connection.HTTPConnection object at 0x7f5adc669d20>: Failed to establish a new connection: [Errno 111] Connection refused'))
INFO 05-15 21:47:47 llm_engine.py:90] Initializing an LLM engine (v0.3.3) with config: model='/vllm/.idea/full_models/Llama-2-13b-hf', tokenizer='/vllm/.idea/full_models/Llama-2-13b-hf', tokenizer_mode=auto, revision=None, tokenizer_revision=None, trust_remote_code=False, dtype=torch.float16, lora_config=None, delta_config=DeltaConfig(max_deltas=16, max_bitwidth=4, delta_dtype=torch.int8, max_cpu_deltas=32, delta_extra_vocab_size=0, pack_factor=Fraction(2, 1), kernel=<QuantKernel.TRITON: 'triton'>), swap_config=None, max_seq_len=4096, download_dir=None, load_format=auto, tensor_parallel_size=4, disable_custom_all_reduce=False, quantization=None, enforce_eager=True, kv_cache_dtype=auto, device_config=cuda, seed=0)
INFO 05-15 21:47:47 llm_engine.py:243] ignored verifying delta_config
Waiting for 10 secs for the system to be ready: HTTPConnectionPool(host='localhost', port=8000): Max retries exceeded with url: /sysinfo (Caused by NewConnectionError('<urllib3.connection.HTTPConnection object at 0x7f5adc668f70>: Failed to establish a new connection: [Errno 111] Connection refused'))
Waiting for 10 secs for the system to be ready: HTTPConnectionPool(host='localhost', port=8000): Max retries exceeded with url: /sysinfo (Caused by NewConnectionError('<urllib3.connection.HTTPConnection object at 0x7f5adc668520>: Failed to establish a new connection: [Errno 111] Connection refused'))
Waiting for 10 secs for the system to be ready: HTTPConnectionPool(host='localhost', port=8000): Max retries exceeded with url: /sysinfo (Caused by NewConnectionError('<urllib3.connection.HTTPConnection object at 0x7f5adc66a5f0>: Failed to establish a new connection: [Errno 111] Connection refused'))
Waiting for 10 secs for the system to be ready: HTTPConnectionPool(host='localhost', port=8000): Max retries exceeded with url: /sysinfo (Caused by NewConnectionError('<urllib3.connection.HTTPConnection object at 0x7f5adc66aec0>: Failed to establish a new connection: [Errno 111] Connection refused'))
Waiting for 10 secs for the system to be ready: HTTPConnectionPool(host='localhost', port=8000): Max retries exceeded with url: /sysinfo (Caused by NewConnectionError('<urllib3.connection.HTTPConnection object at 0x7f5adc643b20>: Failed to establish a new connection: [Errno 111] Connection refused'))
Waiting for 10 secs for the system to be ready: HTTPConnectionPool(host='localhost', port=8000): Max retries exceeded with url: /sysinfo (Caused by NewConnectionError('<urllib3.connection.HTTPConnection object at 0x7f5adc66a860>: Failed to establish a new connection: [Errno 111] Connection refused'))
Waiting for 10 secs for the system to be ready: HTTPConnectionPool(host='localhost', port=8000): Max retries exceeded with url: /sysinfo (Caused by NewConnectionError('<urllib3.connection.HTTPConnection object at 0x7f5adc669f90>: Failed to establish a new connection: [Errno 111] Connection refused'))
Waiting for 10 secs for the system to be ready: HTTPConnectionPool(host='localhost', port=8000): Max retries exceeded with url: /sysinfo (Caused by NewConnectionError('<urllib3.connection.HTTPConnection object at 0x7f5adc668dc0>: Failed to establish a new connection: [Errno 111] Connection refused'))
Waiting for 10 secs for the system to be ready: HTTPConnectionPool(host='localhost', port=8000): Max retries exceeded with url: /sysinfo (Caused by NewConnectionError('<urllib3.connection.HTTPConnection object at 0x7f5adc6698d0>: Failed to establish a new connection: [Errno 111] Connection refused'))
Waiting for 10 secs for the system to be ready: HTTPConnectionPool(host='localhost', port=8000): Max retries exceeded with url: /sysinfo (Caused by NewConnectionError('<urllib3.connection.HTTPConnection object at 0x7f5adc66b790>: Failed to establish a new connection: [Errno 111] Connection refused'))
Waiting for 10 secs for the system to be ready: HTTPConnectionPool(host='localhost', port=8000): Max retries exceeded with url: /sysinfo (Caused by NewConnectionError('<urllib3.connection.HTTPConnection object at 0x7f5adc669c90>: Failed to establish a new connection: [Errno 111] Connection refused'))
Waiting for 10 secs for the system to be ready: HTTPConnectionPool(host='localhost', port=8000): Max retries exceeded with url: /sysinfo (Caused by NewConnectionError('<urllib3.connection.HTTPConnection object at 0x7f5adc6690c0>: Failed to establish a new connection: [Errno 111] Connection refused'))
Waiting for 10 secs for the system to be ready: HTTPConnectionPool(host='localhost', port=8000): Max retries exceeded with url: /sysinfo (Caused by NewConnectionError('<urllib3.connection.HTTPConnection object at 0x7f5adc6681f0>: Failed to establish a new connection: [Errno 111] Connection refused'))
Waiting for 10 secs for the system to be ready: HTTPConnectionPool(host='localhost', port=8000): Max retries exceeded with url: /sysinfo (Caused by NewConnectionError('<urllib3.connection.HTTPConnection object at 0x7f5adc66a2f0>: Failed to establish a new connection: [Errno 111] Connection refused'))
Waiting for 10 secs for the system to be ready: HTTPConnectionPool(host='localhost', port=8000): Max retries exceeded with url: /sysinfo (Caused by NewConnectionError('<urllib3.connection.HTTPConnection object at 0x7f5adc66aa40>: Failed to establish a new connection: [Errno 111] Connection refused'))
Waiting for 10 secs for the system to be ready: HTTPConnectionPool(host='localhost', port=8000): Max retries exceeded with url: /sysinfo (Caused by NewConnectionError('<urllib3.connection.HTTPConnection object at 0x7f5adc6439d0>: Failed to establish a new connection: [Errno 111] Connection refused'))
Waiting for 10 secs for the system to be ready: HTTPConnectionPool(host='localhost', port=8000): Max retries exceeded with url: /sysinfo (Caused by NewConnectionError('<urllib3.connection.HTTPConnection object at 0x7f5adc66a470>: Failed to establish a new connection: [Errno 111] Connection refused'))
Waiting for 10 secs for the system to be ready: HTTPConnectionPool(host='localhost', port=8000): Max retries exceeded with url: /sysinfo (Caused by NewConnectionError('<urllib3.connection.HTTPConnection object at 0x7f5adc668880>: Failed to establish a new connection: [Errno 111] Connection refused'))
Waiting for 10 secs for the system to be ready: HTTPConnectionPool(host='localhost', port=8000): Max retries exceeded with url: /sysinfo (Caused by NewConnectionError('<urllib3.connection.HTTPConnection object at 0x7f5adc669210>: Failed to establish a new connection: [Errno 111] Connection refused'))
Waiting for 10 secs for the system to be ready: HTTPConnectionPool(host='localhost', port=8000): Max retries exceeded with url: /sysinfo (Caused by NewConnectionError('<urllib3.connection.HTTPConnection object at 0x7f5adc669ba0>: Failed to establish a new connection: [Errno 111] Connection refused'))
Waiting for 10 secs for the system to be ready: HTTPConnectionPool(host='localhost', port=8000): Max retries exceeded with url: /sysinfo (Caused by NewConnectionError('<urllib3.connection.HTTPConnection object at 0x7f5adc66b070>: Failed to establish a new connection: [Errno 111] Connection refused'))
Waiting for 10 secs for the system to be ready: HTTPConnectionPool(host='localhost', port=8000): Max retries exceeded with url: /sysinfo (Caused by NewConnectionError('<urllib3.connection.HTTPConnection object at 0x7f5adc66b460>: Failed to establish a new connection: [Errno 111] Connection refused'))
Waiting for 10 secs for the system to be ready: HTTPConnectionPool(host='localhost', port=8000): Max retries exceeded with url: /sysinfo (Caused by NewConnectionError('<urllib3.connection.HTTPConnection object at 0x7f5adc669d50>: Failed to establish a new connection: [Errno 111] Connection refused'))
Waiting for 10 secs for the system to be ready: HTTPConnectionPool(host='localhost', port=8000): Max retries exceeded with url: /sysinfo (Caused by NewConnectionError('<urllib3.connection.HTTPConnection object at 0x7f5adc669450>: Failed to establish a new connection: [Errno 111] Connection refused'))
Waiting for 10 secs for the system to be ready: HTTPConnectionPool(host='localhost', port=8000): Max retries exceeded with url: /sysinfo (Caused by NewConnectionError('<urllib3.connection.HTTPConnection object at 0x7f5adc668190>: Failed to establish a new connection: [Errno 111] Connection refused'))
Waiting for 10 secs for the system to be ready: HTTPConnectionPool(host='localhost', port=8000): Max retries exceeded with url: /sysinfo (Caused by NewConnectionError('<urllib3.connection.HTTPConnection object at 0x7f5adc66a200>: Failed to establish a new connection: [Errno 111] Connection refused'))
Waiting for 10 secs for the system to be ready: HTTPConnectionPool(host='localhost', port=8000): Max retries exceeded with url: /sysinfo (Caused by NewConnectionError('<urllib3.connection.HTTPConnection object at 0x7f5adc66aec0>: Failed to establish a new connection: [Errno 111] Connection refused'))
Waiting for 10 secs for the system to be ready: HTTPConnectionPool(host='localhost', port=8000): Max retries exceeded with url: /sysinfo (Caused by NewConnectionError('<urllib3.connection.HTTPConnection object at 0x7f5adc66a0b0>: Failed to establish a new connection: [Errno 111] Connection refused'))
Waiting for 10 secs for the system to be ready: HTTPConnectionPool(host='localhost', port=8000): Max retries exceeded with url: /sysinfo (Caused by NewConnectionError('<urllib3.connection.HTTPConnection object at 0x7f5adc6683d0>: Failed to establish a new connection: [Errno 111] Connection refused'))
Waiting for 10 secs for the system to be ready: HTTPConnectionPool(host='localhost', port=8000): Max retries exceeded with url: /sysinfo (Caused by NewConnectionError('<urllib3.connection.HTTPConnection object at 0x7f5adc6698a0>: Failed to establish a new connection: [Errno 111] Connection refused'))
Waiting for 10 secs for the system to be ready: HTTPConnectionPool(host='localhost', port=8000): Max retries exceeded with url: /sysinfo (Caused by NewConnectionError('<urllib3.connection.HTTPConnection object at 0x7f5adc66b9a0>: Failed to establish a new connection: [Errno 111] Connection refused'))
Waiting for 10 secs for the system to be ready: HTTPConnectionPool(host='localhost', port=8000): Max retries exceeded with url: /sysinfo (Caused by NewConnectionError('<urllib3.connection.HTTPConnection object at 0x7f5adc66b520>: Failed to establish a new connection: [Errno 111] Connection refused'))
Waiting for 10 secs for the system to be ready: HTTPConnectionPool(host='localhost', port=8000): Max retries exceeded with url: /sysinfo (Caused by NewConnectionError('<urllib3.connection.HTTPConnection object at 0x7f5adc66b7c0>: Failed to establish a new connection: [Errno 111] Connection refused'))
Waiting for 10 secs for the system to be ready: HTTPConnectionPool(host='localhost', port=8000): Max retries exceeded with url: /sysinfo (Caused by NewConnectionError('<urllib3.connection.HTTPConnection object at 0x7f5adc6696c0>: Failed to establish a new connection: [Errno 111] Connection refused'))
Waiting for 10 secs for the system to be ready: HTTPConnectionPool(host='localhost', port=8000): Max retries exceeded with url: /sysinfo (Caused by NewConnectionError('<urllib3.connection.HTTPConnection object at 0x7f5adc6695d0>: Failed to establish a new connection: [Errno 111] Connection refused'))
Waiting for 10 secs for the system to be ready: HTTPConnectionPool(host='localhost', port=8000): Max retries exceeded with url: /sysinfo (Caused by NewConnectionError('<urllib3.connection.HTTPConnection object at 0x7f5adc6684f0>: Failed to establish a new connection: [Errno 111] Connection refused'))
Waiting for 10 secs for the system to be ready: HTTPConnectionPool(host='localhost', port=8000): Max retries exceeded with url: /sysinfo (Caused by NewConnectionError('<urllib3.connection.HTTPConnection object at 0x7f5adc66a290>: Failed to establish a new connection: [Errno 111] Connection refused'))
Waiting for 10 secs for the system to be ready: HTTPConnectionPool(host='localhost', port=8000): Max retries exceeded with url: /sysinfo (Caused by NewConnectionError('<urllib3.connection.HTTPConnection object at 0x7f5adc2400a0>: Failed to establish a new connection: [Errno 111] Connection refused'))
Waiting for 10 secs for the system to be ready: HTTPConnectionPool(host='localhost', port=8000): Max retries exceeded with url: /sysinfo (Caused by NewConnectionError('<urllib3.connection.HTTPConnection object at 0x7f5adc668d90>: Failed to establish a new connection: [Errno 111] Connection refused'))
Waiting for 10 secs for the system to be ready: HTTPConnectionPool(host='localhost', port=8000): Max retries exceeded with url: /sysinfo (Caused by NewConnectionError('<urllib3.connection.HTTPConnection object at 0x7f5adc668fa0>: Failed to establish a new connection: [Errno 111] Connection refused'))
Waiting for 10 secs for the system to be ready: HTTPConnectionPool(host='localhost', port=8000): Max retries exceeded with url: /sysinfo (Caused by NewConnectionError('<urllib3.connection.HTTPConnection object at 0x7f5adc669c90>: Failed to establish a new connection: [Errno 111] Connection refused'))
Waiting for 10 secs for the system to be ready: HTTPConnectionPool(host='localhost', port=8000): Max retries exceeded with url: /sysinfo (Caused by NewConnectionError('<urllib3.connection.HTTPConnection object at 0x7f5adc66b580>: Failed to establish a new connection: [Errno 111] Connection refused'))
Waiting for 10 secs for the system to be ready: HTTPConnectionPool(host='localhost', port=8000): Max retries exceeded with url: /sysinfo (Caused by NewConnectionError('<urllib3.connection.HTTPConnection object at 0x7f5adc643850>: Failed to establish a new connection: [Errno 111] Connection refused'))
Waiting for 10 secs for the system to be ready: HTTPConnectionPool(host='localhost', port=8000): Max retries exceeded with url: /sysinfo (Caused by NewConnectionError('<urllib3.connection.HTTPConnection object at 0x7f5adc66bd30>: Failed to establish a new connection: [Errno 111] Connection refused'))
Waiting for 10 secs for the system to be ready: HTTPConnectionPool(host='localhost', port=8000): Max retries exceeded with url: /sysinfo (Caused by NewConnectionError('<urllib3.connection.HTTPConnection object at 0x7f5adc66b970>: Failed to establish a new connection: [Errno 111] Connection refused'))
Waiting for 10 secs for the system to be ready: HTTPConnectionPool(host='localhost', port=8000): Max retries exceeded with url: /sysinfo (Caused by NewConnectionError('<urllib3.connection.HTTPConnection object at 0x7f5adc669ae0>: Failed to establish a new connection: [Errno 111] Connection refused'))
Waiting for 10 secs for the system to be ready: HTTPConnectionPool(host='localhost', port=8000): Max retries exceeded with url: /sysinfo (Caused by NewConnectionError('<urllib3.connection.HTTPConnection object at 0x7f5adc6694b0>: Failed to establish a new connection: [Errno 111] Connection refused'))
Waiting for 10 secs for the system to be ready: HTTPConnectionPool(host='localhost', port=8000): Max retries exceeded with url: /sysinfo (Caused by NewConnectionError('<urllib3.connection.HTTPConnection object at 0x7f5adc6683a0>: Failed to establish a new connection: [Errno 111] Connection refused'))
Waiting for 10 secs for the system to be ready: HTTPConnectionPool(host='localhost', port=8000): Max retries exceeded with url: /sysinfo (Caused by NewConnectionError('<urllib3.connection.HTTPConnection object at 0x7f5adc668280>: Failed to establish a new connection: [Errno 111] Connection refused'))
Waiting for 10 secs for the system to be ready: HTTPConnectionPool(host='localhost', port=8000): Max retries exceeded with url: /sysinfo (Caused by NewConnectionError('<urllib3.connection.HTTPConnection object at 0x7f5adc66a050>: Failed to establish a new connection: [Errno 111] Connection refused'))
Waiting for 10 secs for the system to be ready: HTTPConnectionPool(host='localhost', port=8000): Max retries exceeded with url: /sysinfo (Caused by NewConnectionError('<urllib3.connection.HTTPConnection object at 0x7f5adc668250>: Failed to establish a new connection: [Errno 111] Connection refused'))
Waiting for 10 secs for the system to be ready: HTTPConnectionPool(host='localhost', port=8000): Max retries exceeded with url: /sysinfo (Caused by NewConnectionError('<urllib3.connection.HTTPConnection object at 0x7f5adc669780>: Failed to establish a new connection: [Errno 111] Connection refused'))
Waiting for 10 secs for the system to be ready: HTTPConnectionPool(host='localhost', port=8000): Max retries exceeded with url: /sysinfo (Caused by NewConnectionError('<urllib3.connection.HTTPConnection object at 0x7f5adc66b790>: Failed to establish a new connection: [Errno 111] Connection refused'))
Waiting for 10 secs for the system to be ready: HTTPConnectionPool(host='localhost', port=8000): Max retries exceeded with url: /sysinfo (Caused by NewConnectionError('<urllib3.connection.HTTPConnection object at 0x7f5adc2404f0>: Failed to establish a new connection: [Errno 111] Connection refused'))
Waiting for 10 secs for the system to be ready: HTTPConnectionPool(host='localhost', port=8000): Max retries exceeded with url: /sysinfo (Caused by NewConnectionError('<urllib3.connection.HTTPConnection object at 0x7f5adc66bdc0>: Failed to establish a new connection: [Errno 111] Connection refused'))
Waiting for 10 secs for the system to be ready: HTTPConnectionPool(host='localhost', port=8000): Max retries exceeded with url: /sysinfo (Caused by NewConnectionError('<urllib3.connection.HTTPConnection object at 0x7f5adc6696f0>: Failed to establish a new connection: [Errno 111] Connection refused'))
Waiting for 10 secs for the system to be ready: HTTPConnectionPool(host='localhost', port=8000): Max retries exceeded with url: /sysinfo (Caused by NewConnectionError('<urllib3.connection.HTTPConnection object at 0x7f5adc669cf0>: Failed to establish a new connection: [Errno 111] Connection refused'))
Waiting for 10 secs for the system to be ready: HTTPConnectionPool(host='localhost', port=8000): Max retries exceeded with url: /sysinfo (Caused by NewConnectionError('<urllib3.connection.HTTPConnection object at 0x7f5adc669840>: Failed to establish a new connection: [Errno 111] Connection refused'))
Using bitblas
WARNING 05-15 21:57:36 models.py:48] Using bitblas delta modules
INFO 05-15 21:57:37 selector.py:16] Using FlashAttention backend.
Waiting for 10 secs for the system to be ready: HTTPConnectionPool(host='localhost', port=8000): Max retries exceeded with url: /sysinfo (Caused by NewConnectionError('<urllib3.connection.HTTPConnection object at 0x7f5adc6686a0>: Failed to establish a new connection: [Errno 111] Connection refused'))
[36m(RayWorkerVllm pid=84564)[0m Exception ignored in: <function TempDirectory.__del__ at 0x7f8188d11c60>
[36m(RayWorkerVllm pid=84564)[0m Traceback (most recent call last):
[36m(RayWorkerVllm pid=84564)[0m   File "/usr/local/lib/python3.10/dist-packages/bitblas/3rdparty/tvm/python/tvm/contrib/utils.py", line 145, in __del__
[36m(RayWorkerVllm pid=84564)[0m     self.remove()
[36m(RayWorkerVllm pid=84564)[0m   File "/usr/local/lib/python3.10/dist-packages/bitblas/3rdparty/tvm/python/tvm/contrib/utils.py", line 121, in remove
[36m(RayWorkerVllm pid=84564)[0m     if self.temp_dir:
[36m(RayWorkerVllm pid=84564)[0m AttributeError: 'TempDirectory' object has no attribute 'temp_dir'
[36m(RayWorkerVllm pid=84375)[0m Exception ignored in: <function TempDirectory.__del__ at 0x7fa95a19dc60>
[36m(RayWorkerVllm pid=84375)[0m Traceback (most recent call last):
[36m(RayWorkerVllm pid=84375)[0m   File "/usr/local/lib/python3.10/dist-packages/bitblas/3rdparty/tvm/python/tvm/contrib/utils.py", line 145, in __del__
[36m(RayWorkerVllm pid=84375)[0m     self.remove()
[36m(RayWorkerVllm pid=84375)[0m   File "/usr/local/lib/python3.10/dist-packages/bitblas/3rdparty/tvm/python/tvm/contrib/utils.py", line 121, in remove
[36m(RayWorkerVllm pid=84375)[0m     if self.temp_dir:
[36m(RayWorkerVllm pid=84375)[0m AttributeError: 'TempDirectory' object has no attribute 'temp_dir'
Waiting for 10 secs for the system to be ready: HTTPConnectionPool(host='localhost', port=8000): Max retries exceeded with url: /sysinfo (Caused by NewConnectionError('<urllib3.connection.HTTPConnection object at 0x7f5adc2409a0>: Failed to establish a new connection: [Errno 111] Connection refused'))
[36m(RayWorkerVllm pid=84375)[0m Exception ignored in: <function TempDirectory.__del__ at 0x7fa95a19dc60>
[36m(RayWorkerVllm pid=84375)[0m Traceback (most recent call last):
[36m(RayWorkerVllm pid=84375)[0m   File "/usr/local/lib/python3.10/dist-packages/bitblas/3rdparty/tvm/python/tvm/contrib/utils.py", line 145, in __del__
[36m(RayWorkerVllm pid=84375)[0m     self.remove()
[36m(RayWorkerVllm pid=84375)[0m   File "/usr/local/lib/python3.10/dist-packages/bitblas/3rdparty/tvm/python/tvm/contrib/utils.py", line 121, in remove
[36m(RayWorkerVllm pid=84375)[0m     if self.temp_dir:
[36m(RayWorkerVllm pid=84375)[0m AttributeError: 'TempDirectory' object has no attribute 'temp_dir'
Waiting for 10 secs for the system to be ready: HTTPConnectionPool(host='localhost', port=8000): Max retries exceeded with url: /sysinfo (Caused by NewConnectionError('<urllib3.connection.HTTPConnection object at 0x7f5adc668d60>: Failed to establish a new connection: [Errno 111] Connection refused'))
Waiting for 10 secs for the system to be ready: HTTPConnectionPool(host='localhost', port=8000): Max retries exceeded with url: /sysinfo (Caused by NewConnectionError('<urllib3.connection.HTTPConnection object at 0x7f5adc669810>: Failed to establish a new connection: [Errno 111] Connection refused'))
Waiting for 10 secs for the system to be ready: HTTPConnectionPool(host='localhost', port=8000): Max retries exceeded with url: /sysinfo (Caused by NewConnectionError('<urllib3.connection.HTTPConnection object at 0x7f5adc66b0d0>: Failed to establish a new connection: [Errno 111] Connection refused'))
Waiting for 10 secs for the system to be ready: HTTPConnectionPool(host='localhost', port=8000): Max retries exceeded with url: /sysinfo (Caused by NewConnectionError('<urllib3.connection.HTTPConnection object at 0x7f5adc66b460>: Failed to establish a new connection: [Errno 111] Connection refused'))
Waiting for 10 secs for the system to be ready: HTTPConnectionPool(host='localhost', port=8000): Max retries exceeded with url: /sysinfo (Caused by NewConnectionError('<urllib3.connection.HTTPConnection object at 0x7f5adc240310>: Failed to establish a new connection: [Errno 111] Connection refused'))
Waiting for 10 secs for the system to be ready: HTTPConnectionPool(host='localhost', port=8000): Max retries exceeded with url: /sysinfo (Caused by NewConnectionError('<urllib3.connection.HTTPConnection object at 0x7f5adc66bca0>: Failed to establish a new connection: [Errno 111] Connection refused'))
Waiting for 10 secs for the system to be ready: HTTPConnectionPool(host='localhost', port=8000): Max retries exceeded with url: /sysinfo (Caused by NewConnectionError('<urllib3.connection.HTTPConnection object at 0x7f5adc66b5b0>: Failed to establish a new connection: [Errno 111] Connection refused'))
Waiting for 10 secs for the system to be ready: HTTPConnectionPool(host='localhost', port=8000): Max retries exceeded with url: /sysinfo (Caused by NewConnectionError('<urllib3.connection.HTTPConnection object at 0x7f5adc66ba90>: Failed to establish a new connection: [Errno 111] Connection refused'))
Waiting for 10 secs for the system to be ready: HTTPConnectionPool(host='localhost', port=8000): Max retries exceeded with url: /sysinfo (Caused by NewConnectionError('<urllib3.connection.HTTPConnection object at 0x7f5adc669960>: Failed to establish a new connection: [Errno 111] Connection refused'))
Waiting for 10 secs for the system to be ready: HTTPConnectionPool(host='localhost', port=8000): Max retries exceeded with url: /sysinfo (Caused by NewConnectionError('<urllib3.connection.HTTPConnection object at 0x7f5adc669f00>: Failed to establish a new connection: [Errno 111] Connection refused'))
Waiting for 10 secs for the system to be ready: HTTPConnectionPool(host='localhost', port=8000): Max retries exceeded with url: /sysinfo (Caused by NewConnectionError('<urllib3.connection.HTTPConnection object at 0x7f5adc240790>: Failed to establish a new connection: [Errno 111] Connection refused'))
Waiting for 10 secs for the system to be ready: HTTPConnectionPool(host='localhost', port=8000): Max retries exceeded with url: /sysinfo (Caused by NewConnectionError('<urllib3.connection.HTTPConnection object at 0x7f5adc669cc0>: Failed to establish a new connection: [Errno 111] Connection refused'))
Waiting for 10 secs for the system to be ready: HTTPConnectionPool(host='localhost', port=8000): Max retries exceeded with url: /sysinfo (Caused by NewConnectionError('<urllib3.connection.HTTPConnection object at 0x7f5adc66b820>: Failed to establish a new connection: [Errno 111] Connection refused'))
Waiting for 10 secs for the system to be ready: HTTPConnectionPool(host='localhost', port=8000): Max retries exceeded with url: /sysinfo (Caused by NewConnectionError('<urllib3.connection.HTTPConnection object at 0x7f5adc66b2e0>: Failed to establish a new connection: [Errno 111] Connection refused'))
Waiting for 10 secs for the system to be ready: HTTPConnectionPool(host='localhost', port=8000): Max retries exceeded with url: /sysinfo (Caused by NewConnectionError('<urllib3.connection.HTTPConnection object at 0x7f5adc66b370>: Failed to establish a new connection: [Errno 111] Connection refused'))
Waiting for 10 secs for the system to be ready: HTTPConnectionPool(host='localhost', port=8000): Max retries exceeded with url: /sysinfo (Caused by NewConnectionError('<urllib3.connection.HTTPConnection object at 0x7f5adc240be0>: Failed to establish a new connection: [Errno 111] Connection refused'))
Waiting for 10 secs for the system to be ready: HTTPConnectionPool(host='localhost', port=8000): Max retries exceeded with url: /sysinfo (Caused by NewConnectionError('<urllib3.connection.HTTPConnection object at 0x7f5adc66bfa0>: Failed to establish a new connection: [Errno 111] Connection refused'))
Waiting for 10 secs for the system to be ready: HTTPConnectionPool(host='localhost', port=8000): Max retries exceeded with url: /sysinfo (Caused by NewConnectionError('<urllib3.connection.HTTPConnection object at 0x7f5adc6696f0>: Failed to establish a new connection: [Errno 111] Connection refused'))
Waiting for 10 secs for the system to be ready: HTTPConnectionPool(host='localhost', port=8000): Max retries exceeded with url: /sysinfo (Caused by NewConnectionError('<urllib3.connection.HTTPConnection object at 0x7f5adc669cf0>: Failed to establish a new connection: [Errno 111] Connection refused'))
Waiting for 10 secs for the system to be ready: HTTPConnectionPool(host='localhost', port=8000): Max retries exceeded with url: /sysinfo (Caused by NewConnectionError('<urllib3.connection.HTTPConnection object at 0x7f5adc669840>: Failed to establish a new connection: [Errno 111] Connection refused'))
