/mnt/hwfile/huqinghao/miniconda3/bin/python
2024-06-12 21:49:37,385 - INFO - Note: detected 128 virtual cores but NumExpr set to maximum of 64, check "NUMEXPR_MAX_THREADS" environment variable.
2024-06-12 21:49:37,385 - INFO - Note: NumExpr detected 128 cores but "NUMEXPR_MAX_THREADS" not set, so enforcing safe limit of 8.
2024-06-12 21:49:37,385 - INFO - NumExpr defaulting to 8 threads.
2024-06-12 21:49:38,897	INFO scripts.py:1182 -- Did not find any active Ray processes.

==========
== CUDA ==
==========

CUDA Version 12.1.0

Container image Copyright (c) 2016-2023, NVIDIA CORPORATION & AFFILIATES. All rights reserved.

This container image and its contents are governed by the NVIDIA Deep Learning Container License.
By pulling and using the container, you accept the terms and conditions of this license:
https://developer.nvidia.com/ngc/nvidia-deep-learning-container-license

A copy of this license is made available in this container at /NGC-DL-CONTAINER-LICENSE for your convenience.
Waiting for 10 secs for the system to be ready: HTTPConnectionPool(host='localhost', port=8000): Max retries exceeded with url: /sysinfo (Caused by NewConnectionError('<urllib3.connection.HTTPConnection object at 0x7f3eaa560a30>: Failed to establish a new connection: [Errno 111] Connection refused'))

*************************
** DEPRECATION NOTICE! **
*************************
THIS IMAGE IS DEPRECATED and is scheduled for DELETION.
    https://gitlab.com/nvidia/container-images/cuda/blob/master/doc/support-policy.md

Waiting for 10 secs for the system to be ready: HTTPConnectionPool(host='localhost', port=8000): Max retries exceeded with url: /sysinfo (Caused by NewConnectionError('<urllib3.connection.HTTPConnection object at 0x7f3eaa5613c0>: Failed to establish a new connection: [Errno 111] Connection refused'))
Delta policy is enabled
Waiting for 10 secs for the system to be ready: HTTPConnectionPool(host='localhost', port=8000): Max retries exceeded with url: /sysinfo (Caused by NewConnectionError('<urllib3.connection.HTTPConnection object at 0x7f3eaa561c90>: Failed to establish a new connection: [Errno 111] Connection refused'))
INFO 06-12 21:50:03 api_server.py:191] vLLM API server version 0.3.3
INFO 06-12 21:50:03 api_server.py:192] args: Namespace(host=None, port=8000, uvicorn_log_level='info', allow_credentials=False, allowed_origins=['*'], allowed_methods=['*'], allowed_headers=['*'], api_key=None, served_model_name=None, lora_modules=[], delta_modules=[Delta(name='delta-1', local_path='/vllm/.idea/models/13b/4bit/deltazip.lmsys.vicuna-13b-v1.5.4bn2m4-1g-1'), Delta(name='delta-2', local_path='/vllm/.idea/models/13b/4bit/deltazip.lmsys.vicuna-13b-v1.5.4bn2m4-1g-2'), Delta(name='delta-3', local_path='/vllm/.idea/models/13b/4bit/deltazip.lmsys.vicuna-13b-v1.5.4bn2m4-1g-3'), Delta(name='delta-4', local_path='/vllm/.idea/models/13b/4bit/deltazip.lmsys.vicuna-13b-v1.5.4bn2m4-1g-4'), Delta(name='delta-5', local_path='/vllm/.idea/models/13b/4bit/deltazip.lmsys.vicuna-13b-v1.5.4bn2m4-1g-5'), Delta(name='delta-6', local_path='/vllm/.idea/models/13b/4bit/deltazip.lmsys.vicuna-13b-v1.5.4bn2m4-1g-6'), Delta(name='delta-7', local_path='/vllm/.idea/models/13b/4bit/deltazip.lmsys.vicuna-13b-v1.5.4bn2m4-1g-7'), Delta(name='delta-8', local_path='/vllm/.idea/models/13b/4bit/deltazip.lmsys.vicuna-13b-v1.5.4bn2m4-1g-8'), Delta(name='delta-9', local_path='/vllm/.idea/models/13b/4bit/deltazip.lmsys.vicuna-13b-v1.5.4bn2m4-1g-9'), Delta(name='delta-10', local_path='/vllm/.idea/models/13b/4bit/deltazip.lmsys.vicuna-13b-v1.5.4bn2m4-1g-10'), Delta(name='delta-11', local_path='/vllm/.idea/models/13b/4bit/deltazip.lmsys.vicuna-13b-v1.5.4bn2m4-1g-11'), Delta(name='delta-12', local_path='/vllm/.idea/models/13b/4bit/deltazip.lmsys.vicuna-13b-v1.5.4bn2m4-1g-12'), Delta(name='delta-13', local_path='/vllm/.idea/models/13b/4bit/deltazip.lmsys.vicuna-13b-v1.5.4bn2m4-1g-13'), Delta(name='delta-14', local_path='/vllm/.idea/models/13b/4bit/deltazip.lmsys.vicuna-13b-v1.5.4bn2m4-1g-14'), Delta(name='delta-15', local_path='/vllm/.idea/models/13b/4bit/deltazip.lmsys.vicuna-13b-v1.5.4bn2m4-1g-15'), Delta(name='delta-16', local_path='/vllm/.idea/models/13b/4bit/deltazip.lmsys.vicuna-13b-v1.5.4bn2m4-1g-16'), Delta(name='delta-17', local_path='/vllm/.idea/models/13b/4bit/deltazip.lmsys.vicuna-13b-v1.5.4bn2m4-1g-17'), Delta(name='delta-18', local_path='/vllm/.idea/models/13b/4bit/deltazip.lmsys.vicuna-13b-v1.5.4bn2m4-1g-18'), Delta(name='delta-19', local_path='/vllm/.idea/models/13b/4bit/deltazip.lmsys.vicuna-13b-v1.5.4bn2m4-1g-19'), Delta(name='delta-20', local_path='/vllm/.idea/models/13b/4bit/deltazip.lmsys.vicuna-13b-v1.5.4bn2m4-1g-20'), Delta(name='delta-21', local_path='/vllm/.idea/models/13b/4bit/deltazip.lmsys.vicuna-13b-v1.5.4bn2m4-1g-21'), Delta(name='delta-22', local_path='/vllm/.idea/models/13b/4bit/deltazip.lmsys.vicuna-13b-v1.5.4bn2m4-1g-22'), Delta(name='delta-23', local_path='/vllm/.idea/models/13b/4bit/deltazip.lmsys.vicuna-13b-v1.5.4bn2m4-1g-23'), Delta(name='delta-24', local_path='/vllm/.idea/models/13b/4bit/deltazip.lmsys.vicuna-13b-v1.5.4bn2m4-1g-24'), Delta(name='delta-25', local_path='/vllm/.idea/models/13b/4bit/deltazip.lmsys.vicuna-13b-v1.5.4bn2m4-1g-25'), Delta(name='delta-26', local_path='/vllm/.idea/models/13b/4bit/deltazip.lmsys.vicuna-13b-v1.5.4bn2m4-1g-26'), Delta(name='delta-27', local_path='/vllm/.idea/models/13b/4bit/deltazip.lmsys.vicuna-13b-v1.5.4bn2m4-1g-27'), Delta(name='delta-28', local_path='/vllm/.idea/models/13b/4bit/deltazip.lmsys.vicuna-13b-v1.5.4bn2m4-1g-28'), Delta(name='delta-29', local_path='/vllm/.idea/models/13b/4bit/deltazip.lmsys.vicuna-13b-v1.5.4bn2m4-1g-29'), Delta(name='delta-30', local_path='/vllm/.idea/models/13b/4bit/deltazip.lmsys.vicuna-13b-v1.5.4bn2m4-1g-30'), Delta(name='delta-31', local_path='/vllm/.idea/models/13b/4bit/deltazip.lmsys.vicuna-13b-v1.5.4bn2m4-1g-31'), Delta(name='delta-32', local_path='/vllm/.idea/models/13b/4bit/deltazip.lmsys.vicuna-13b-v1.5.4bn2m4-1g-32')], swap_modules=[], chat_template=None, response_role='assistant', ssl_keyfile=None, ssl_certfile=None, ssl_ca_certs=None, ssl_cert_reqs=0, root_path=None, middleware=[], model='/vllm/.idea/full_models/Llama-2-13b-hf', tokenizer=None, revision=None, code_revision=None, tokenizer_revision=None, tokenizer_mode='auto', trust_remote_code=False, download_dir=None, load_format='auto', dtype='auto', kv_cache_dtype='auto', max_model_len=None, worker_use_ray=False, pipeline_parallel_size=1, tensor_parallel_size=4, max_parallel_loading_workers=None, ray_workers_use_nsight=False, block_size=16, enable_prefix_caching=False, seed=0, swap_space=4, gpu_memory_utilization=0.85, max_num_batched_tokens=None, max_num_seqs=256, max_logprobs=5, disable_log_stats=False, quantization=None, enforce_eager=True, max_context_len_to_capture=8192, disable_custom_all_reduce=False, tokenizer_pool_size=0, tokenizer_pool_type='ray', tokenizer_pool_extra_config=None, enable_lora=False, max_loras=1, max_lora_rank=64, lora_extra_vocab_size=256, lora_dtype='auto', max_cpu_loras=32, enable_delta=True, max_deltas=12, max_cpu_deltas=32, max_delta_bitwidth=4, device='auto', image_input_type=None, image_token_id=None, image_input_shape=None, image_feature_size=None, scheduler_delay_factor=0.0, enable_prefetch=False, scheduler_policy='fcfs', max_swap_slots=1, max_cpu_models=4, enable_swap=False, engine_use_ray=False, disable_log_requests=True, max_log_len=None)
2024-06-12 21:50:07,019	INFO worker.py:1749 -- Started a local Ray instance.
INFO 06-12 21:50:09 llm_engine.py:90] Initializing an LLM engine (v0.3.3) with config: model='/vllm/.idea/full_models/Llama-2-13b-hf', tokenizer='/vllm/.idea/full_models/Llama-2-13b-hf', tokenizer_mode=auto, revision=None, tokenizer_revision=None, trust_remote_code=False, dtype=torch.float16, lora_config=None, delta_config=DeltaConfig(max_deltas=12, max_bitwidth=4, delta_dtype=torch.int32, max_cpu_deltas=32, delta_extra_vocab_size=0, pack_factor=Fraction(8, 1), sparse_factor=Fraction(2, 1), kernel=<QuantKernel.TRITON: 'triton'>), swap_config=None, max_seq_len=4096, download_dir=None, load_format=auto, tensor_parallel_size=4, disable_custom_all_reduce=False, quantization=None, enforce_eager=True, kv_cache_dtype=auto, device_config=cuda, seed=0)
INFO 06-12 21:50:09 llm_engine.py:243] ignored verifying delta_config
Waiting for 10 secs for the system to be ready: HTTPConnectionPool(host='localhost', port=8000): Max retries exceeded with url: /sysinfo (Caused by NewConnectionError('<urllib3.connection.HTTPConnection object at 0x7f3eaa562560>: Failed to establish a new connection: [Errno 111] Connection refused'))
slurmstepd: error: *** JOB 3696657 ON HOST-10-140-60-14 CANCELLED AT 2024-06-12T21:50:12 ***
[failure_signal_handler.cc : 332] RAW: Signal 15 raised at PC=0x7f2c1fdafdc0 while already in AbslFailureSignalHandler()
*** SIGTERM received at time=1718200212 on cpu 52 ***
PC: @     0x7f2c1fdafdc0  (unknown)  _IO_default_xsputn
    @     0x7f2c1fd64520       5760  (unknown)
    @     0x7f2c1fd97336       1488  (unknown)
    @     0x7f2b6feed280  (unknown)  (unknown)
[2024-06-12 21:50:12,107 E 74507 74507] logging.cc:365: *** SIGTERM received at time=1718200212 on cpu 52 ***
[2024-06-12 21:50:12,109 E 74507 74507] logging.cc:365: PC: @     0x7f2c1fdafdc0  (unknown)  _IO_default_xsputn
[2024-06-12 21:50:12,112 E 74507 74507] logging.cc:365:     @     0x7f2c1fd64520       5760  (unknown)
[2024-06-12 21:50:12,114 E 74507 74507] logging.cc:365:     @     0x7f2c1fd97336       1488  (unknown)
[2024-06-12 21:50:12,117 E 74507 74507] logging.cc:365:     @     0x7f2b6feed280  (unknown)  (unknown)
*** SIGTERM received at time=1718200212 on cpu 116 ***
PC: @     0x7f2c1fdb3117  (unknown)  (unknown)
    @     0x7f2c1fd64520  (unknown)  (unknown)
    @ ... and at least 1 more frames
[2024-06-12 21:50:12,127 E 74507 74507] logging.cc:365: *** SIGTERM received at time=1718200212 on cpu 116 ***
[2024-06-12 21:50:12,128 E 74507 74507] logging.cc:365: PC: @     0x7f2c1fdb3117  (unknown)  (unknown)
[2024-06-12 21:50:12,130 E 74507 74507] logging.cc:365:     @     0x7f2c1fd64520  (unknown)  (unknown)
[2024-06-12 21:50:12,131 E 74507 74507] logging.cc:365:     @ ... and at least 1 more frames
