/mnt/hwfile/huqinghao/miniconda3/bin/python
2024-05-06 03:02:19,652 - INFO - Note: detected 128 virtual cores but NumExpr set to maximum of 64, check "NUMEXPR_MAX_THREADS" environment variable.
2024-05-06 03:02:19,653 - INFO - Note: NumExpr detected 128 cores but "NUMEXPR_MAX_THREADS" not set, so enforcing safe limit of 8.
2024-05-06 03:02:19,653 - INFO - NumExpr defaulting to 8 threads.
2024-05-06 03:02:20,574	INFO scripts.py:1182 -- Did not find any active Ray processes.

==========
== CUDA ==
==========

CUDA Version 12.1.0

Container image Copyright (c) 2016-2023, NVIDIA CORPORATION & AFFILIATES. All rights reserved.

This container image and its contents are governed by the NVIDIA Deep Learning Container License.
By pulling and using the container, you accept the terms and conditions of this license:
https://developer.nvidia.com/ngc/nvidia-deep-learning-container-license

A copy of this license is made available in this container at /NGC-DL-CONTAINER-LICENSE for your convenience.

*************************
** DEPRECATION NOTICE! **
*************************
THIS IMAGE IS DEPRECATED and is scheduled for DELETION.
    https://gitlab.com/nvidia/container-images/cuda/blob/master/doc/support-policy.md

Waiting for 10 secs for the system to be ready: HTTPConnectionPool(host='localhost', port=8000): Max retries exceeded with url: /sysinfo (Caused by NewConnectionError('<urllib3.connection.HTTPConnection object at 0x7f9fd4fc4490>: Failed to establish a new connection: [Errno 111] Connection refused'))
/usr/local/lib/python3.10/dist-packages/pydantic/_internal/_fields.py:160: UserWarning: Field "model_name_or_path" has conflict with protected namespace "model_".

You may be able to resolve this warning by setting `model_config['protected_namespaces'] = ()`.
  warnings.warn(
Waiting for 10 secs for the system to be ready: HTTPConnectionPool(host='localhost', port=8000): Max retries exceeded with url: /sysinfo (Caused by NewConnectionError('<urllib3.connection.HTTPConnection object at 0x7f9fd4fc5210>: Failed to establish a new connection: [Errno 111] Connection refused'))
INFO 05-06 03:02:32 api_server.py:202] vLLM API server version 0.3.3
INFO 05-06 03:02:32 api_server.py:203] args: Namespace(host=None, port=8000, uvicorn_log_level='info', allow_credentials=False, allowed_origins=['*'], allowed_methods=['*'], allowed_headers=['*'], api_key=None, served_model_name=None, lora_modules=[], delta_modules=[Delta(name='delta-1', local_path='/vllm/.idea/models/70b/llama2-chat-70b.4b75s128g-bitblas-tp_4-1'), Delta(name='delta-2', local_path='/vllm/.idea/models/70b/llama2-chat-70b.4b75s128g-bitblas-tp_4-2'), Delta(name='delta-3', local_path='/vllm/.idea/models/70b/llama2-chat-70b.4b75s128g-bitblas-tp_4-3'), Delta(name='delta-4', local_path='/vllm/.idea/models/70b/llama2-chat-70b.4b75s128g-bitblas-tp_4-4'), Delta(name='delta-5', local_path='/vllm/.idea/models/70b/llama2-chat-70b.4b75s128g-bitblas-tp_4-5'), Delta(name='delta-6', local_path='/vllm/.idea/models/70b/llama2-chat-70b.4b75s128g-bitblas-tp_4-6'), Delta(name='delta-7', local_path='/vllm/.idea/models/70b/llama2-chat-70b.4b75s128g-bitblas-tp_4-7'), Delta(name='delta-8', local_path='/vllm/.idea/models/70b/llama2-chat-70b.4b75s128g-bitblas-tp_4-8')], swap_modules=[], chat_template=None, response_role='assistant', ssl_keyfile=None, ssl_certfile=None, ssl_ca_certs=None, ssl_cert_reqs=0, root_path=None, middleware=[], model='/vllm/.idea/full_models/llama-70b', tokenizer=None, revision=None, code_revision=None, tokenizer_revision=None, tokenizer_mode='auto', trust_remote_code=False, download_dir=None, load_format='auto', dtype='auto', kv_cache_dtype='auto', max_model_len=None, worker_use_ray=False, pipeline_parallel_size=1, tensor_parallel_size=4, max_parallel_loading_workers=None, ray_workers_use_nsight=False, block_size=16, enable_prefix_caching=False, seed=0, swap_space=4, gpu_memory_utilization=0.85, max_num_batched_tokens=None, max_num_seqs=256, max_logprobs=5, disable_log_stats=False, quantization=None, enforce_eager=True, max_context_len_to_capture=8192, disable_custom_all_reduce=False, tokenizer_pool_size=0, tokenizer_pool_type='ray', tokenizer_pool_extra_config=None, enable_lora=False, max_loras=1, max_lora_rank=64, lora_extra_vocab_size=256, lora_dtype='auto', max_cpu_loras=32, enable_delta=True, max_deltas=4, max_cpu_deltas=32, max_delta_bitwidth=4, device='auto', image_input_type=None, image_token_id=None, image_input_shape=None, image_feature_size=None, scheduler_delay_factor=0.0, enable_prefetch=False, engine_use_ray=False, disable_log_requests=True, max_log_len=None)
2024-05-06 03:02:35,940	INFO worker.py:1749 -- Started a local Ray instance.
INFO 05-06 03:02:38 llm_engine.py:87] Initializing an LLM engine (v0.3.3) with config: model='/vllm/.idea/full_models/llama-70b', tokenizer='/vllm/.idea/full_models/llama-70b', tokenizer_mode=auto, revision=None, tokenizer_revision=None, trust_remote_code=False, dtype=torch.float16, lora_config=None, delta_config=DeltaConfig(max_deltas=4, max_bitwidth=4, delta_dtype=torch.int8, max_cpu_deltas=32, delta_extra_vocab_size=0, pack_factor=Fraction(2, 1), kernel=<QuantKernel.TRITON: 'triton'>), max_seq_len=4096, download_dir=None, load_format=auto, tensor_parallel_size=4, disable_custom_all_reduce=False, quantization=None, enforce_eager=True, kv_cache_dtype=auto, device_config=cuda, seed=0)
INFO 05-06 03:02:38 llm_engine.py:237] ignored verifying delta_config
Waiting for 10 secs for the system to be ready: HTTPConnectionPool(host='localhost', port=8000): Max retries exceeded with url: /sysinfo (Caused by NewConnectionError('<urllib3.connection.HTTPConnection object at 0x7f9fd4fc5ae0>: Failed to establish a new connection: [Errno 111] Connection refused'))
Waiting for 10 secs for the system to be ready: HTTPConnectionPool(host='localhost', port=8000): Max retries exceeded with url: /sysinfo (Caused by NewConnectionError('<urllib3.connection.HTTPConnection object at 0x7f9fd4fc5a50>: Failed to establish a new connection: [Errno 111] Connection refused'))
Waiting for 10 secs for the system to be ready: HTTPConnectionPool(host='localhost', port=8000): Max retries exceeded with url: /sysinfo (Caused by NewConnectionError('<urllib3.connection.HTTPConnection object at 0x7f9fd4fc5180>: Failed to establish a new connection: [Errno 111] Connection refused'))
Waiting for 10 secs for the system to be ready: HTTPConnectionPool(host='localhost', port=8000): Max retries exceeded with url: /sysinfo (Caused by NewConnectionError('<urllib3.connection.HTTPConnection object at 0x7f9fd4fc40d0>: Failed to establish a new connection: [Errno 111] Connection refused'))
Waiting for 10 secs for the system to be ready: HTTPConnectionPool(host='localhost', port=8000): Max retries exceeded with url: /sysinfo (Caused by NewConnectionError('<urllib3.connection.HTTPConnection object at 0x7f9fd4fc63b0>: Failed to establish a new connection: [Errno 111] Connection refused'))
Waiting for 10 secs for the system to be ready: HTTPConnectionPool(host='localhost', port=8000): Max retries exceeded with url: /sysinfo (Caused by NewConnectionError('<urllib3.connection.HTTPConnection object at 0x7f9fd4fc6c80>: Failed to establish a new connection: [Errno 111] Connection refused'))
Waiting for 10 secs for the system to be ready: HTTPConnectionPool(host='localhost', port=8000): Max retries exceeded with url: /sysinfo (Caused by NewConnectionError('<urllib3.connection.HTTPConnection object at 0x7f9fd4fc6440>: Failed to establish a new connection: [Errno 111] Connection refused'))
Waiting for 10 secs for the system to be ready: HTTPConnectionPool(host='localhost', port=8000): Max retries exceeded with url: /sysinfo (Caused by NewConnectionError('<urllib3.connection.HTTPConnection object at 0x7f9fd4fc4190>: Failed to establish a new connection: [Errno 111] Connection refused'))
Waiting for 10 secs for the system to be ready: HTTPConnectionPool(host='localhost', port=8000): Max retries exceeded with url: /sysinfo (Caused by NewConnectionError('<urllib3.connection.HTTPConnection object at 0x7f9fd4fc5270>: Failed to establish a new connection: [Errno 111] Connection refused'))
Waiting for 10 secs for the system to be ready: HTTPConnectionPool(host='localhost', port=8000): Max retries exceeded with url: /sysinfo (Caused by NewConnectionError('<urllib3.connection.HTTPConnection object at 0x7f9fd4fc5b40>: Failed to establish a new connection: [Errno 111] Connection refused'))
Waiting for 10 secs for the system to be ready: HTTPConnectionPool(host='localhost', port=8000): Max retries exceeded with url: /sysinfo (Caused by NewConnectionError('<urllib3.connection.HTTPConnection object at 0x7f9fd4fc5b70>: Failed to establish a new connection: [Errno 111] Connection refused'))
Waiting for 10 secs for the system to be ready: HTTPConnectionPool(host='localhost', port=8000): Max retries exceeded with url: /sysinfo (Caused by NewConnectionError('<urllib3.connection.HTTPConnection object at 0x7f9fd4fc7550>: Failed to establish a new connection: [Errno 111] Connection refused'))
Waiting for 10 secs for the system to be ready: HTTPConnectionPool(host='localhost', port=8000): Max retries exceeded with url: /sysinfo (Caused by NewConnectionError('<urllib3.connection.HTTPConnection object at 0x7f9fd4fc5600>: Failed to establish a new connection: [Errno 111] Connection refused'))
Waiting for 10 secs for the system to be ready: HTTPConnectionPool(host='localhost', port=8000): Max retries exceeded with url: /sysinfo (Caused by NewConnectionError('<urllib3.connection.HTTPConnection object at 0x7f9fd4fc4d30>: Failed to establish a new connection: [Errno 111] Connection refused'))
Using bitblas
WARNING 05-06 03:04:54 models.py:48] Using bitblas delta modules
INFO 05-06 03:04:54 selector.py:16] Using FlashAttention backend.
Waiting for 10 secs for the system to be ready: HTTPConnectionPool(host='localhost', port=8000): Max retries exceeded with url: /sysinfo (Caused by NewConnectionError('<urllib3.connection.HTTPConnection object at 0x7f9fd4fc5f90>: Failed to establish a new connection: [Errno 111] Connection refused'))
[36m(RayWorkerVllm pid=49922)[0m Exception ignored in: <function TempDirectory.__del__ at 0x7f02ad9d4c10>
[36m(RayWorkerVllm pid=49922)[0m Traceback (most recent call last):
[36m(RayWorkerVllm pid=49922)[0m   File "/usr/local/lib/python3.10/dist-packages/bitblas/3rdparty/tvm/python/tvm/contrib/utils.py", line 145, in __del__
[36m(RayWorkerVllm pid=49922)[0m     self.remove()
[36m(RayWorkerVllm pid=49922)[0m   File "/usr/local/lib/python3.10/dist-packages/bitblas/3rdparty/tvm/python/tvm/contrib/utils.py", line 121, in remove
[36m(RayWorkerVllm pid=49922)[0m     if self.temp_dir:
[36m(RayWorkerVllm pid=49922)[0m AttributeError: 'TempDirectory' object has no attribute 'temp_dir'
[36m(RayWorkerVllm pid=50838)[0m Exception ignored in: <function TempDirectory.__del__ at 0x7efbb75e0c10>
[36m(RayWorkerVllm pid=50838)[0m Traceback (most recent call last):
[36m(RayWorkerVllm pid=50838)[0m   File "/usr/local/lib/python3.10/dist-packages/bitblas/3rdparty/tvm/python/tvm/contrib/utils.py", line 145, in __del__
[36m(RayWorkerVllm pid=50838)[0m     self.remove()
[36m(RayWorkerVllm pid=50838)[0m   File "/usr/local/lib/python3.10/dist-packages/bitblas/3rdparty/tvm/python/tvm/contrib/utils.py", line 121, in remove
[36m(RayWorkerVllm pid=50838)[0m     if self.temp_dir:
[36m(RayWorkerVllm pid=50838)[0m AttributeError: 'TempDirectory' object has no attribute 'temp_dir'
[36m(RayWorkerVllm pid=50838)[0m Exception ignored in: <function TempDirectory.__del__ at 0x7efbb75e0c10>
[36m(RayWorkerVllm pid=50838)[0m Traceback (most recent call last):
[36m(RayWorkerVllm pid=50838)[0m   File "/usr/local/lib/python3.10/dist-packages/bitblas/3rdparty/tvm/python/tvm/contrib/utils.py", line 145, in __del__
[36m(RayWorkerVllm pid=50838)[0m     self.remove()
[36m(RayWorkerVllm pid=50838)[0m   File "/usr/local/lib/python3.10/dist-packages/bitblas/3rdparty/tvm/python/tvm/contrib/utils.py", line 121, in remove
[36m(RayWorkerVllm pid=50838)[0m     if self.temp_dir:
[36m(RayWorkerVllm pid=50838)[0m AttributeError: 'TempDirectory' object has no attribute 'temp_dir'
Waiting for 10 secs for the system to be ready: HTTPConnectionPool(host='localhost', port=8000): Max retries exceeded with url: /sysinfo (Caused by NewConnectionError('<urllib3.connection.HTTPConnection object at 0x7f9fd4fc6860>: Failed to establish a new connection: [Errno 111] Connection refused'))
Waiting for 10 secs for the system to be ready: HTTPConnectionPool(host='localhost', port=8000): Max retries exceeded with url: /sysinfo (Caused by NewConnectionError('<urllib3.connection.HTTPConnection object at 0x7f9fd4fc71c0>: Failed to establish a new connection: [Errno 111] Connection refused'))
Waiting for 10 secs for the system to be ready: HTTPConnectionPool(host='localhost', port=8000): Max retries exceeded with url: /sysinfo (Caused by NewConnectionError('<urllib3.connection.HTTPConnection object at 0x7f9fd4fc6ce0>: Failed to establish a new connection: [Errno 111] Connection refused'))
Waiting for 10 secs for the system to be ready: HTTPConnectionPool(host='localhost', port=8000): Max retries exceeded with url: /sysinfo (Caused by NewConnectionError('<urllib3.connection.HTTPConnection object at 0x7f9fd4fc6410>: Failed to establish a new connection: [Errno 111] Connection refused'))
Waiting for 10 secs for the system to be ready: HTTPConnectionPool(host='localhost', port=8000): Max retries exceeded with url: /sysinfo (Caused by NewConnectionError('<urllib3.connection.HTTPConnection object at 0x7f9fd4fc4160>: Failed to establish a new connection: [Errno 111] Connection refused'))
Waiting for 10 secs for the system to be ready: HTTPConnectionPool(host='localhost', port=8000): Max retries exceeded with url: /sysinfo (Caused by NewConnectionError('<urllib3.connection.HTTPConnection object at 0x7f9fd4fc51b0>: Failed to establish a new connection: [Errno 111] Connection refused'))
Waiting for 10 secs for the system to be ready: HTTPConnectionPool(host='localhost', port=8000): Max retries exceeded with url: /sysinfo (Caused by NewConnectionError('<urllib3.connection.HTTPConnection object at 0x7f9fd4fc5720>: Failed to establish a new connection: [Errno 111] Connection refused'))
Waiting for 10 secs for the system to be ready: HTTPConnectionPool(host='localhost', port=8000): Max retries exceeded with url: /sysinfo (Caused by NewConnectionError('<urllib3.connection.HTTPConnection object at 0x7f9fd4fc7220>: Failed to establish a new connection: [Errno 111] Connection refused'))
Waiting for 10 secs for the system to be ready: HTTPConnectionPool(host='localhost', port=8000): Max retries exceeded with url: /sysinfo (Caused by NewConnectionError('<urllib3.connection.HTTPConnection object at 0x7f9fd4fc5450>: Failed to establish a new connection: [Errno 111] Connection refused'))
Waiting for 10 secs for the system to be ready: HTTPConnectionPool(host='localhost', port=8000): Max retries exceeded with url: /sysinfo (Caused by NewConnectionError('<urllib3.connection.HTTPConnection object at 0x7f9fd4fc4b80>: Failed to establish a new connection: [Errno 111] Connection refused'))
Waiting for 10 secs for the system to be ready: HTTPConnectionPool(host='localhost', port=8000): Max retries exceeded with url: /sysinfo (Caused by NewConnectionError('<urllib3.connection.HTTPConnection object at 0x7f9fd4fc61a0>: Failed to establish a new connection: [Errno 111] Connection refused'))
Waiting for 10 secs for the system to be ready: HTTPConnectionPool(host='localhost', port=8000): Max retries exceeded with url: /sysinfo (Caused by NewConnectionError('<urllib3.connection.HTTPConnection object at 0x7f9fd4fc6a70>: Failed to establish a new connection: [Errno 111] Connection refused'))
Waiting for 10 secs for the system to be ready: HTTPConnectionPool(host='localhost', port=8000): Max retries exceeded with url: /sysinfo (Caused by NewConnectionError('<urllib3.connection.HTTPConnection object at 0x7f9fd4fc7070>: Failed to establish a new connection: [Errno 111] Connection refused'))
Waiting for 10 secs for the system to be ready: HTTPConnectionPool(host='localhost', port=8000): Max retries exceeded with url: /sysinfo (Caused by NewConnectionError('<urllib3.connection.HTTPConnection object at 0x7f9fd4fc7610>: Failed to establish a new connection: [Errno 111] Connection refused'))
[36m(RayWorkerVllm pid=49922)[0m Using bitblas
[36m(RayWorkerVllm pid=50838)[0m Using bitblas
[36m(RayWorkerVllm pid=51448)[0m Using bitblas
[36m(RayWorkerVllm pid=49922)[0m BitBLAS Operator not loaded, retrying in 5 seconds...
[36m(RayWorkerVllm pid=49922)[0m Error: [Errno 17] File exists: '/home/xiayao/.cache/bitblas/nvidia/nvidia-a100/c96df0f34eb23be516ef0126651d4e78b151337f28ebc87cc5492d79d135855f/tvm_rt_mod'
[36m(RayWorkerVllm pid=50838)[0m BitBLAS Operator not loaded, retrying in 5 seconds...
[36m(RayWorkerVllm pid=50838)[0m Error: [Errno 17] File exists: '/home/xiayao/.cache/bitblas/nvidia/nvidia-a100/c96df0f34eb23be516ef0126651d4e78b151337f28ebc87cc5492d79d135855f/tvm_rt_mod'
[36m(RayWorkerVllm pid=50838)[0m BitBLAS Operator not loaded, retrying in 5 seconds...
[36m(RayWorkerVllm pid=50838)[0m Error: [Errno 17] File exists: '/home/xiayao/.cache/bitblas/nvidia/nvidia-a100/c96df0f34eb23be516ef0126651d4e78b151337f28ebc87cc5492d79d135855f/tvm_rt_mod'
[36m(RayWorkerVllm pid=51448)[0m WARNING 05-06 03:06:49 models.py:48] Using bitblas delta modules
[36m(RayWorkerVllm pid=51448)[0m INFO 05-06 03:06:49 selector.py:16] Using FlashAttention backend.
[36m(RayWorkerVllm pid=49922)[0m WARNING 05-06 03:06:54 models.py:48] Using bitblas delta modules
[36m(RayWorkerVllm pid=49922)[0m INFO 05-06 03:06:54 selector.py:16] Using FlashAttention backend.
[36m(RayWorkerVllm pid=50838)[0m WARNING 05-06 03:07:00 models.py:48] Using bitblas delta modules
[36m(RayWorkerVllm pid=50838)[0m INFO 05-06 03:07:00 selector.py:16] Using FlashAttention backend.
INFO 05-06 03:07:28 model_runner.py:155] Loading model weights took 32.1245 GB
INFO 05-06 03:07:28 worker_manager.py:293] Starting prefetching thread
Waiting for 10 secs for the system to be ready: HTTPConnectionPool(host='localhost', port=8000): Max retries exceeded with url: /sysinfo (Caused by NewConnectionError('<urllib3.connection.HTTPConnection object at 0x7f9fd4fc67d0>: Failed to establish a new connection: [Errno 111] Connection refused'))
[36m(RayWorkerVllm pid=51448)[0m INFO 05-06 03:07:36 model_runner.py:155] Loading model weights took 32.1245 GB
[36m(RayWorkerVllm pid=51448)[0m INFO 05-06 03:07:36 worker_manager.py:293] Starting prefetching thread
[36m(RayWorkerVllm pid=50838)[0m INFO 05-06 03:07:37 model_runner.py:155] Loading model weights took 32.1245 GB
[36m(RayWorkerVllm pid=50838)[0m INFO 05-06 03:07:37 worker_manager.py:293] Starting prefetching thread
[36m(RayWorkerVllm pid=49922)[0m INFO 05-06 03:07:37 model_runner.py:155] Loading model weights took 32.1245 GB
[36m(RayWorkerVllm pid=49922)[0m INFO 05-06 03:07:37 worker_manager.py:293] Starting prefetching thread
WARNING 05-06 03:07:38 quant_linear_triton.py:557] We should warm up the kernel here 
Waiting for 10 secs for the system to be ready: HTTPConnectionPool(host='localhost', port=8000): Max retries exceeded with url: /sysinfo (Caused by NewConnectionError('<urllib3.connection.HTTPConnection object at 0x7f9fd4fc6680>: Failed to establish a new connection: [Errno 111] Connection refused'))
Waiting for 10 secs for the system to be ready: HTTPConnectionPool(host='localhost', port=8000): Max retries exceeded with url: /sysinfo (Caused by NewConnectionError('<urllib3.connection.HTTPConnection object at 0x7f9fd4fc4310>: Failed to establish a new connection: [Errno 111] Connection refused'))
Waiting for 10 secs for the system to be ready: HTTPConnectionPool(host='localhost', port=8000): Max retries exceeded with url: /sysinfo (Caused by NewConnectionError('<urllib3.connection.HTTPConnection object at 0x7f9fd4fc50c0>: Failed to establish a new connection: [Errno 111] Connection refused'))
[36m(RayWorkerVllm pid=51448)[0m WARNING 05-06 03:07:49 quant_linear_triton.py:557] We should warm up the kernel here 
[36m(RayWorkerVllm pid=50838)[0m WARNING 05-06 03:07:49 quant_linear_triton.py:557] We should warm up the kernel here 
[36m(RayWorkerVllm pid=49922)[0m WARNING 05-06 03:07:50 quant_linear_triton.py:557] We should warm up the kernel here 
INFO 05-06 03:08:03 ray_gpu_executor.py:266] # GPU blocks: 0, # CPU blocks: 3276
Traceback (most recent call last):
  File "/vllm/vllm/entrypoints/openai/api_server.py", line 211, in <module>
    engine = AsyncLLMEngine.from_engine_args(engine_args)
  File "/vllm/vllm/engine/async_llm_engine.py", line 386, in from_engine_args
    engine = cls(
  File "/vllm/vllm/engine/async_llm_engine.py", line 346, in __init__
    self.engine = self._init_engine(*args, **kwargs)
  File "/vllm/vllm/engine/async_llm_engine.py", line 471, in _init_engine
    return engine_class(*args, **kwargs)
  File "/vllm/vllm/engine/llm_engine.py", line 126, in __init__
    self.model_executor = executor_class(
  File "/vllm/vllm/executor/ray_gpu_executor.py", line 81, in __init__
    self._init_cache()
  File "/vllm/vllm/executor/ray_gpu_executor.py", line 270, in _init_cache
    check_block_size_valid(
  File "/vllm/vllm/executor/utils.py", line 3, in check_block_size_valid
    raise ValueError(
ValueError: No available memory for the cache blocks. Try increasing `gpu_memory_utilization` when initializing the engine.
Waiting for 10 secs for the system to be ready: HTTPConnectionPool(host='localhost', port=8000): Max retries exceeded with url: /sysinfo (Caused by NewConnectionError('<urllib3.connection.HTTPConnection object at 0x7f9fd4fc73d0>: Failed to establish a new connection: [Errno 111] Connection refused'))
Waiting for 10 secs for the system to be ready: HTTPConnectionPool(host='localhost', port=8000): Max retries exceeded with url: /sysinfo (Caused by NewConnectionError('<urllib3.connection.HTTPConnection object at 0x7f9fd4fc43a0>: Failed to establish a new connection: [Errno 111] Connection refused'))
Waiting for 10 secs for the system to be ready: HTTPConnectionPool(host='localhost', port=8000): Max retries exceeded with url: /sysinfo (Caused by NewConnectionError('<urllib3.connection.HTTPConnection object at 0x7f9fd4fc6560>: Failed to establish a new connection: [Errno 111] Connection refused'))
Waiting for 10 secs for the system to be ready: HTTPConnectionPool(host='localhost', port=8000): Max retries exceeded with url: /sysinfo (Caused by NewConnectionError('<urllib3.connection.HTTPConnection object at 0x7f9fd4fc6ec0>: Failed to establish a new connection: [Errno 111] Connection refused'))
Waiting for 10 secs for the system to be ready: HTTPConnectionPool(host='localhost', port=8000): Max retries exceeded with url: /sysinfo (Caused by NewConnectionError('<urllib3.connection.HTTPConnection object at 0x7f9fd4fc7820>: Failed to establish a new connection: [Errno 111] Connection refused'))
Waiting for 10 secs for the system to be ready: HTTPConnectionPool(host='localhost', port=8000): Max retries exceeded with url: /sysinfo (Caused by NewConnectionError('<urllib3.connection.HTTPConnection object at 0x7f9fd4fc77f0>: Failed to establish a new connection: [Errno 111] Connection refused'))
Waiting for 10 secs for the system to be ready: HTTPConnectionPool(host='localhost', port=8000): Max retries exceeded with url: /sysinfo (Caused by NewConnectionError('<urllib3.connection.HTTPConnection object at 0x7f9fd4fc5d80>: Failed to establish a new connection: [Errno 111] Connection refused'))
Waiting for 10 secs for the system to be ready: HTTPConnectionPool(host='localhost', port=8000): Max retries exceeded with url: /sysinfo (Caused by NewConnectionError('<urllib3.connection.HTTPConnection object at 0x7f9fd4fc71c0>: Failed to establish a new connection: [Errno 111] Connection refused'))
Waiting for 10 secs for the system to be ready: HTTPConnectionPool(host='localhost', port=8000): Max retries exceeded with url: /sysinfo (Caused by NewConnectionError('<urllib3.connection.HTTPConnection object at 0x7f9fd4fc6f20>: Failed to establish a new connection: [Errno 111] Connection refused'))
Waiting for 10 secs for the system to be ready: HTTPConnectionPool(host='localhost', port=8000): Max retries exceeded with url: /sysinfo (Caused by NewConnectionError('<urllib3.connection.HTTPConnection object at 0x7f9fd4fc65c0>: Failed to establish a new connection: [Errno 111] Connection refused'))
Waiting for 10 secs for the system to be ready: HTTPConnectionPool(host='localhost', port=8000): Max retries exceeded with url: /sysinfo (Caused by NewConnectionError('<urllib3.connection.HTTPConnection object at 0x7f9fd4fc4370>: Failed to establish a new connection: [Errno 111] Connection refused'))
Waiting for 10 secs for the system to be ready: HTTPConnectionPool(host='localhost', port=8000): Max retries exceeded with url: /sysinfo (Caused by NewConnectionError('<urllib3.connection.HTTPConnection object at 0x7f9fd4fc7e20>: Failed to establish a new connection: [Errno 111] Connection refused'))
Waiting for 10 secs for the system to be ready: HTTPConnectionPool(host='localhost', port=8000): Max retries exceeded with url: /sysinfo (Caused by NewConnectionError('<urllib3.connection.HTTPConnection object at 0x7f9fd4fc4bb0>: Failed to establish a new connection: [Errno 111] Connection refused'))
Waiting for 10 secs for the system to be ready: HTTPConnectionPool(host='localhost', port=8000): Max retries exceeded with url: /sysinfo (Caused by NewConnectionError('<urllib3.connection.HTTPConnection object at 0x7f9fd4fc6650>: Failed to establish a new connection: [Errno 111] Connection refused'))
Waiting for 10 secs for the system to be ready: HTTPConnectionPool(host='localhost', port=8000): Max retries exceeded with url: /sysinfo (Caused by NewConnectionError('<urllib3.connection.HTTPConnection object at 0x7f9fd4fc6d70>: Failed to establish a new connection: [Errno 111] Connection refused'))
Waiting for 10 secs for the system to be ready: HTTPConnectionPool(host='localhost', port=8000): Max retries exceeded with url: /sysinfo (Caused by NewConnectionError('<urllib3.connection.HTTPConnection object at 0x7f9fd4fc7310>: Failed to establish a new connection: [Errno 111] Connection refused'))
Waiting for 10 secs for the system to be ready: HTTPConnectionPool(host='localhost', port=8000): Max retries exceeded with url: /sysinfo (Caused by NewConnectionError('<urllib3.connection.HTTPConnection object at 0x7f9fd4fc7550>: Failed to establish a new connection: [Errno 111] Connection refused'))
Waiting for 10 secs for the system to be ready: HTTPConnectionPool(host='localhost', port=8000): Max retries exceeded with url: /sysinfo (Caused by NewConnectionError('<urllib3.connection.HTTPConnection object at 0x7f9fd4fc5c60>: Failed to establish a new connection: [Errno 111] Connection refused'))
Waiting for 10 secs for the system to be ready: HTTPConnectionPool(host='localhost', port=8000): Max retries exceeded with url: /sysinfo (Caused by NewConnectionError('<urllib3.connection.HTTPConnection object at 0x7f9fd4fc6e00>: Failed to establish a new connection: [Errno 111] Connection refused'))
Waiting for 10 secs for the system to be ready: HTTPConnectionPool(host='localhost', port=8000): Max retries exceeded with url: /sysinfo (Caused by NewConnectionError('<urllib3.connection.HTTPConnection object at 0x7f9fd4fc6530>: Failed to establish a new connection: [Errno 111] Connection refused'))
Waiting for 10 secs for the system to be ready: HTTPConnectionPool(host='localhost', port=8000): Max retries exceeded with url: /sysinfo (Caused by NewConnectionError('<urllib3.connection.HTTPConnection object at 0x7f9fd4fc5f30>: Failed to establish a new connection: [Errno 111] Connection refused'))
Waiting for 10 secs for the system to be ready: HTTPConnectionPool(host='localhost', port=8000): Max retries exceeded with url: /sysinfo (Caused by NewConnectionError('<urllib3.connection.HTTPConnection object at 0x7f9fd4fc4670>: Failed to establish a new connection: [Errno 111] Connection refused'))
Waiting for 10 secs for the system to be ready: HTTPConnectionPool(host='localhost', port=8000): Max retries exceeded with url: /sysinfo (Caused by NewConnectionError('<urllib3.connection.HTTPConnection object at 0x7f9fd4fc7d90>: Failed to establish a new connection: [Errno 111] Connection refused'))
Waiting for 10 secs for the system to be ready: HTTPConnectionPool(host='localhost', port=8000): Max retries exceeded with url: /sysinfo (Caused by NewConnectionError('<urllib3.connection.HTTPConnection object at 0x7f9fd4fc6170>: Failed to establish a new connection: [Errno 111] Connection refused'))
Waiting for 10 secs for the system to be ready: HTTPConnectionPool(host='localhost', port=8000): Max retries exceeded with url: /sysinfo (Caused by NewConnectionError('<urllib3.connection.HTTPConnection object at 0x7f9fd4fc7760>: Failed to establish a new connection: [Errno 111] Connection refused'))
Waiting for 10 secs for the system to be ready: HTTPConnectionPool(host='localhost', port=8000): Max retries exceeded with url: /sysinfo (Caused by NewConnectionError('<urllib3.connection.HTTPConnection object at 0x7f9fd4fc5750>: Failed to establish a new connection: [Errno 111] Connection refused'))
Waiting for 10 secs for the system to be ready: HTTPConnectionPool(host='localhost', port=8000): Max retries exceeded with url: /sysinfo (Caused by NewConnectionError('<urllib3.connection.HTTPConnection object at 0x7f9fd4fc75e0>: Failed to establish a new connection: [Errno 111] Connection refused'))
Waiting for 10 secs for the system to be ready: HTTPConnectionPool(host='localhost', port=8000): Max retries exceeded with url: /sysinfo (Caused by NewConnectionError('<urllib3.connection.HTTPConnection object at 0x7f9fd4f9b8e0>: Failed to establish a new connection: [Errno 111] Connection refused'))
Waiting for 10 secs for the system to be ready: HTTPConnectionPool(host='localhost', port=8000): Max retries exceeded with url: /sysinfo (Caused by NewConnectionError('<urllib3.connection.HTTPConnection object at 0x7f9fd4fc5ba0>: Failed to establish a new connection: [Errno 111] Connection refused'))
Waiting for 10 secs for the system to be ready: HTTPConnectionPool(host='localhost', port=8000): Max retries exceeded with url: /sysinfo (Caused by NewConnectionError('<urllib3.connection.HTTPConnection object at 0x7f9fd4fc7790>: Failed to establish a new connection: [Errno 111] Connection refused'))
Waiting for 10 secs for the system to be ready: HTTPConnectionPool(host='localhost', port=8000): Max retries exceeded with url: /sysinfo (Caused by NewConnectionError('<urllib3.connection.HTTPConnection object at 0x7f9fd4fc4190>: Failed to establish a new connection: [Errno 111] Connection refused'))
Waiting for 10 secs for the system to be ready: HTTPConnectionPool(host='localhost', port=8000): Max retries exceeded with url: /sysinfo (Caused by NewConnectionError('<urllib3.connection.HTTPConnection object at 0x7f9fd4fc5270>: Failed to establish a new connection: [Errno 111] Connection refused'))
Waiting for 10 secs for the system to be ready: HTTPConnectionPool(host='localhost', port=8000): Max retries exceeded with url: /sysinfo (Caused by NewConnectionError('<urllib3.connection.HTTPConnection object at 0x7f9fd4fc62f0>: Failed to establish a new connection: [Errno 111] Connection refused'))
Waiting for 10 secs for the system to be ready: HTTPConnectionPool(host='localhost', port=8000): Max retries exceeded with url: /sysinfo (Caused by NewConnectionError('<urllib3.connection.HTTPConnection object at 0x7f9fd4b88760>: Failed to establish a new connection: [Errno 111] Connection refused'))
Waiting for 10 secs for the system to be ready: HTTPConnectionPool(host='localhost', port=8000): Max retries exceeded with url: /sysinfo (Caused by NewConnectionError('<urllib3.connection.HTTPConnection object at 0x7f9fd4fc6710>: Failed to establish a new connection: [Errno 111] Connection refused'))
Waiting for 10 secs for the system to be ready: HTTPConnectionPool(host='localhost', port=8000): Max retries exceeded with url: /sysinfo (Caused by NewConnectionError('<urllib3.connection.HTTPConnection object at 0x7f9fd4fc69e0>: Failed to establish a new connection: [Errno 111] Connection refused'))
slurmstepd: error: *** JOB 3666638 ON HOST-10-140-60-3 CANCELLED AT 2024-05-06T03:14:04 ***
[failure_signal_handler.cc : 332] RAW: Signal 15 raised at PC=0x7f2ac46142f0 while already in AbslFailureSignalHandler()
*** SIGTERM received at time=1714936444 on cpu 63 ***
PC: @     0x7f2ac46142f0  (unknown)  absl::lts_20230125::debugging_internal::FailureSignalToString()
    @     0x7f2c146ef520       3504  (unknown)
    @     0x7f2ac46144af         80  absl::lts_20230125::AbslFailureSignalHandler()
    @     0x7f2c146ef520  (unknown)  (unknown)
[2024-05-06 03:14:04,082 E 42021 42021] logging.cc:365: *** SIGTERM received at time=1714936444 on cpu 63 ***
[2024-05-06 03:14:04,082 E 42021 42021] logging.cc:365: PC: @     0x7f2ac46142f0  (unknown)  absl::lts_20230125::debugging_internal::FailureSignalToString()
[2024-05-06 03:14:04,082 E 42021 42021] logging.cc:365:     @     0x7f2c146ef520       3504  (unknown)
[2024-05-06 03:14:04,082 E 42021 42021] logging.cc:365:     @     0x7f2ac46144af         80  absl::lts_20230125::AbslFailureSignalHandler()
[2024-05-06 03:14:04,082 E 42021 42021] logging.cc:365:     @     0x7f2c146ef520  (unknown)  (unknown)
*** SIGTERM received at time=1714936444 on cpu 63 ***
PC: @     0x7f2c1473e117  (unknown)  (unknown)
    @     0x7f2c146ef520  (unknown)  (unknown)
[2024-05-06 03:14:04,083 E 42021 42021] logging.cc:365: *** SIGTERM received at time=1714936444 on cpu 63 ***
[2024-05-06 03:14:04,083 E 42021 42021] logging.cc:365: PC: @     0x7f2c1473e117  (unknown)  (unknown)
[2024-05-06 03:14:04,085 E 42021 42021] logging.cc:365:     @     0x7f2c146ef520  (unknown)  (unknown)
Exception ignored in: <module 'threading' from '/usr/lib/python3.10/threading.py'>
Traceback (most recent call last):
  File "/usr/lib/python3.10/threading.py", line 1567, in _shutdown
    lock.acquire()
  File "/usr/local/lib/python3.10/dist-packages/ray/_private/worker.py", line 1414, in sigterm_handler
    sys.exit(signum)
SystemExit: 15
