/mnt/hwfile/huqinghao/miniconda3/bin/python
2024-05-11 04:32:22,209 - INFO - Note: detected 128 virtual cores but NumExpr set to maximum of 64, check "NUMEXPR_MAX_THREADS" environment variable.
2024-05-11 04:32:22,209 - INFO - Note: NumExpr detected 128 cores but "NUMEXPR_MAX_THREADS" not set, so enforcing safe limit of 8.
2024-05-11 04:32:22,209 - INFO - NumExpr defaulting to 8 threads.
2024-05-11 04:32:23,581	INFO scripts.py:1182 -- Did not find any active Ray processes.

==========
== CUDA ==
==========

CUDA Version 12.1.0

Container image Copyright (c) 2016-2023, NVIDIA CORPORATION & AFFILIATES. All rights reserved.

This container image and its contents are governed by the NVIDIA Deep Learning Container License.
By pulling and using the container, you accept the terms and conditions of this license:
https://developer.nvidia.com/ngc/nvidia-deep-learning-container-license

A copy of this license is made available in this container at /NGC-DL-CONTAINER-LICENSE for your convenience.

*************************
** DEPRECATION NOTICE! **
*************************
THIS IMAGE IS DEPRECATED and is scheduled for DELETION.
    https://gitlab.com/nvidia/container-images/cuda/blob/master/doc/support-policy.md

Waiting for 10 secs for the system to be ready: HTTPConnectionPool(host='localhost', port=8000): Max retries exceeded with url: /sysinfo (Caused by NewConnectionError('<urllib3.connection.HTTPConnection object at 0x7f2f6878c760>: Failed to establish a new connection: [Errno 111] Connection refused'))
/usr/local/lib/python3.10/dist-packages/pydantic/_internal/_fields.py:160: UserWarning: Field "model_name_or_path" has conflict with protected namespace "model_".

You may be able to resolve this warning by setting `model_config['protected_namespaces'] = ()`.
  warnings.warn(
Waiting for 10 secs for the system to be ready: HTTPConnectionPool(host='localhost', port=8000): Max retries exceeded with url: /sysinfo (Caused by NewConnectionError('<urllib3.connection.HTTPConnection object at 0x7f2f6878d0f0>: Failed to establish a new connection: [Errno 111] Connection refused'))
INFO 05-11 04:32:38 api_server.py:209] vLLM API server version 0.3.3
INFO 05-11 04:32:38 api_server.py:210] args: Namespace(host=None, port=8000, uvicorn_log_level='info', allow_credentials=False, allowed_origins=['*'], allowed_methods=['*'], allowed_headers=['*'], api_key=None, served_model_name=None, lora_modules=[], delta_modules=[Delta(name='delta-1', local_path='/vllm/.idea/models/13b/lmsys.vicuna-13b-v1.5.4b75s128g-1'), Delta(name='delta-2', local_path='/vllm/.idea/models/13b/lmsys.vicuna-13b-v1.5.4b75s128g-2'), Delta(name='delta-3', local_path='/vllm/.idea/models/13b/lmsys.vicuna-13b-v1.5.4b75s128g-3'), Delta(name='delta-4', local_path='/vllm/.idea/models/13b/lmsys.vicuna-13b-v1.5.4b75s128g-4'), Delta(name='delta-5', local_path='/vllm/.idea/models/13b/lmsys.vicuna-13b-v1.5.4b75s128g-5'), Delta(name='delta-6', local_path='/vllm/.idea/models/13b/lmsys.vicuna-13b-v1.5.4b75s128g-6'), Delta(name='delta-7', local_path='/vllm/.idea/models/13b/lmsys.vicuna-13b-v1.5.4b75s128g-7'), Delta(name='delta-8', local_path='/vllm/.idea/models/13b/lmsys.vicuna-13b-v1.5.4b75s128g-8')], swap_modules=[], chat_template=None, response_role='assistant', ssl_keyfile=None, ssl_certfile=None, ssl_ca_certs=None, ssl_cert_reqs=0, root_path=None, middleware=[], model='/vllm/.idea/full_models/Llama-2-13b-hf', tokenizer=None, revision=None, code_revision=None, tokenizer_revision=None, tokenizer_mode='auto', trust_remote_code=False, download_dir=None, load_format='auto', dtype='auto', kv_cache_dtype='auto', max_model_len=None, worker_use_ray=False, pipeline_parallel_size=1, tensor_parallel_size=4, max_parallel_loading_workers=None, ray_workers_use_nsight=False, block_size=16, enable_prefix_caching=False, seed=0, swap_space=4, gpu_memory_utilization=0.8, max_num_batched_tokens=None, max_num_seqs=256, max_logprobs=5, disable_log_stats=False, quantization=None, enforce_eager=True, max_context_len_to_capture=8192, disable_custom_all_reduce=False, tokenizer_pool_size=0, tokenizer_pool_type='ray', tokenizer_pool_extra_config=None, enable_lora=False, max_loras=1, max_lora_rank=64, lora_extra_vocab_size=256, lora_dtype='auto', max_cpu_loras=32, enable_delta=True, max_deltas=8, max_cpu_deltas=32, max_delta_bitwidth=4, device='auto', image_input_type=None, image_token_id=None, image_input_shape=None, image_feature_size=None, scheduler_delay_factor=0.0, enable_prefetch=True, scheduler_policy='fcfs', engine_use_ray=False, disable_log_requests=True, max_log_len=None)
2024-05-11 04:32:41,381	INFO worker.py:1749 -- Started a local Ray instance.
slurmstepd: error: *** JOB 3669900 ON HOST-10-140-60-8 CANCELLED AT 2024-05-11T04:32:42 ***
*** SIGTERM received at time=1715373162 on cpu 81 ***
[failure_signal_handler.cc : 332] RAW: Signal 15 raised at PC=0x7f6793a76c1b while already in AbslFailureSignalHandler()
*** SIGTERM received at time=1715373162 on cpu 81 ***
PC: @     0x7f6793a76c1b  (unknown)  pthread_sigmask
    @     0x7f6793a1d520       3920  (unknown)
    @     0x7f6643918f01         80  absl::lts_20230125::debugging_internal::(anonymous namespace)::Symbolizer::RegisterObjFile()
    @     0x7f6643919463        208  absl::lts_20230125::debugging_internal::ReadAddrMap()
    @     0x7f6643919741         80  absl::lts_20230125::debugging_internal::(anonymous namespace)::Symbolizer::FindObjFile()
    @     0x7f664391978e       1296  absl::lts_20230125::debugging_internal::(anonymous namespace)::Symbolizer::GetUncachedSymbol()
    @     0x7f664391a28b         80  absl::lts_20230125::Symbolize()
    @     0x7f664391481d       2144  absl::lts_20230125::debugging_internal::(anonymous namespace)::DumpPCAndFrameSizeAndSymbol()
    @     0x7f6643914951        192  absl::lts_20230125::debugging_internal::DumpPCAndFrameSizesAndStackTrace()
    @     0x7f66439142b6        496  absl::lts_20230125::WriteStackTrace()
    @     0x7f66439144c1         80  absl::lts_20230125::AbslFailureSignalHandler()
    @     0x7f6793a1d520   11444800  (unknown)
    @     0x7f66438fb662         80  boost::asio::detail::socket_ops::sync_recv1()
    @     0x7f664322b568        112  ray::ServerConnection::ReadBuffer()
    @     0x7f664322cb82        496  ray::ServerConnection::ReadMessage()
    @     0x7f6643062988        112  ray::raylet::RayletConnection::AtomicRequestReply()
    @     0x7f6643065b59        416  ray::raylet::RayletClient::RayletClient()
    @     0x7f6642fc043b       1248  ray::core::CoreWorker::CoreWorker()
    @     0x7f6642fc6791        624  ray::core::CoreWorkerProcessImpl::CoreWorkerProcessImpl()
    @     0x7f6642fc767f         80  ray::core::CoreWorkerProcess::Initialize()
    @     0x7f6642e86fdf       2016  __pyx_pw_3ray_7_raylet_10CoreWorker_1__cinit__()
    @     0x7f6642e88299         48  __pyx_tp_new_3ray_7_raylet_CoreWorker()
    @     0x55e532b0f9c7  (unknown)  _PyObject_MakeTpCall
    @     0x55e532f30ba0  (unknown)  (unknown)
[2024-05-11 04:32:42,517 E 100618 100618] logging.cc:365: *** SIGTERM received at time=1715373162 on cpu 81 ***
[2024-05-11 04:32:42,517 E 100618 100618] logging.cc:365: PC: @     0x7f6793a76c1b  (unknown)  pthread_sigmask
[2024-05-11 04:32:42,519 E 100618 100618] logging.cc:365:     @     0x7f6793a1d520       3920  (unknown)
[2024-05-11 04:32:42,519 E 100618 100618] logging.cc:365:     @     0x7f6643918f01         80  absl::lts_20230125::debugging_internal::(anonymous namespace)::Symbolizer::RegisterObjFile()
[2024-05-11 04:32:42,519 E 100618 100618] logging.cc:365:     @     0x7f6643919463        208  absl::lts_20230125::debugging_internal::ReadAddrMap()
[2024-05-11 04:32:42,519 E 100618 100618] logging.cc:365:     @     0x7f6643919741         80  absl::lts_20230125::debugging_internal::(anonymous namespace)::Symbolizer::FindObjFile()
[2024-05-11 04:32:42,519 E 100618 100618] logging.cc:365:     @     0x7f664391978e       1296  absl::lts_20230125::debugging_internal::(anonymous namespace)::Symbolizer::GetUncachedSymbol()
[2024-05-11 04:32:42,519 E 100618 100618] logging.cc:365:     @     0x7f664391a28b         80  absl::lts_20230125::Symbolize()
[2024-05-11 04:32:42,519 E 100618 100618] logging.cc:365:     @     0x7f664391481d       2144  absl::lts_20230125::debugging_internal::(anonymous namespace)::DumpPCAndFrameSizeAndSymbol()
[2024-05-11 04:32:42,519 E 100618 100618] logging.cc:365:     @     0x7f6643914951        192  absl::lts_20230125::debugging_internal::DumpPCAndFrameSizesAndStackTrace()
[2024-05-11 04:32:42,519 E 100618 100618] logging.cc:365:     @     0x7f66439142b6        496  absl::lts_20230125::WriteStackTrace()
[2024-05-11 04:32:42,519 E 100618 100618] logging.cc:365:     @     0x7f66439144c1         80  absl::lts_20230125::AbslFailureSignalHandler()
[2024-05-11 04:32:42,519 E 100618 100618] logging.cc:365:     @     0x7f6793a1d520   11444800  (unknown)
[2024-05-11 04:32:42,519 E 100618 100618] logging.cc:365:     @     0x7f66438fb662         80  boost::asio::detail::socket_ops::sync_recv1()
[2024-05-11 04:32:42,519 E 100618 100618] logging.cc:365:     @     0x7f664322b568        112  ray::ServerConnection::ReadBuffer()
[2024-05-11 04:32:42,519 E 100618 100618] logging.cc:365:     @     0x7f664322cb82        496  ray::ServerConnection::ReadMessage()
[2024-05-11 04:32:42,519 E 100618 100618] logging.cc:365:     @     0x7f6643062988        112  ray::raylet::RayletConnection::AtomicRequestReply()
[2024-05-11 04:32:42,519 E 100618 100618] logging.cc:365:     @     0x7f6643065b59        416  ray::raylet::RayletClient::RayletClient()
[2024-05-11 04:32:42,519 E 100618 100618] logging.cc:365:     @     0x7f6642fc043b       1248  ray::core::CoreWorker::CoreWorker()
[2024-05-11 04:32:42,519 E 100618 100618] logging.cc:365:     @     0x7f6642fc6791        624  ray::core::CoreWorkerProcessImpl::CoreWorkerProcessImpl()
[2024-05-11 04:32:42,519 E 100618 100618] logging.cc:365:     @     0x7f6642fc767f         80  ray::core::CoreWorkerProcess::Initialize()
[2024-05-11 04:32:42,519 E 100618 100618] logging.cc:365:     @     0x7f6642e86fdf       2016  __pyx_pw_3ray_7_raylet_10CoreWorker_1__cinit__()
[2024-05-11 04:32:42,519 E 100618 100618] logging.cc:365:     @     0x7f6642e88299         48  __pyx_tp_new_3ray_7_raylet_CoreWorker()
[2024-05-11 04:32:42,519 E 100618 100618] logging.cc:365:     @     0x55e532b0f9c7  (unknown)  _PyObject_MakeTpCall
[2024-05-11 04:32:42,521 E 100618 100618] logging.cc:365:     @     0x55e532f30ba0  (unknown)  (unknown)
PC: @     0x7f6793b028ae  (unknown)  __recv
    @     0x7f6793a1d520   11444800  (unknown)
    @     0x7f66438fb662         80  boost::asio::detail::socket_ops::sync_recv1()
    @     0x7f664322b568        112  ray::ServerConnection::ReadBuffer()
    @     0x7f664322cb82        496  ray::ServerConnection::ReadMessage()
    @     0x7f6643062988        112  ray::raylet::RayletConnection::AtomicRequestReply()
    @     0x7f6643065b59        416  ray::raylet::RayletClient::RayletClient()
    @     0x7f6642fc043b       1248  ray::core::CoreWorker::CoreWorker()
    @     0x7f6642fc6791        624  ray::core::CoreWorkerProcessImpl::CoreWorkerProcessImpl()
    @     0x7f6642fc767f         80  ray::core::CoreWorkerProcess::Initialize()
    @     0x7f6642e86fdf       2016  __pyx_pw_3ray_7_raylet_10CoreWorker_1__cinit__()
    @     0x7f6642e88299         48  __pyx_tp_new_3ray_7_raylet_CoreWorker()
    @     0x55e532b0f9c7  (unknown)  _PyObject_MakeTpCall
    @     0x55e532f30ba0  (unknown)  (unknown)
[2024-05-11 04:32:42,526 E 100618 100618] logging.cc:365: *** SIGTERM received at time=1715373162 on cpu 81 ***
[2024-05-11 04:32:42,528 E 100618 100618] logging.cc:365: PC: @     0x7f6793b028ae  (unknown)  __recv
[2024-05-11 04:32:42,528 E 100618 100618] logging.cc:365:     @     0x7f6793a1d520   11444800  (unknown)
[2024-05-11 04:32:42,528 E 100618 100618] logging.cc:365:     @     0x7f66438fb662         80  boost::asio::detail::socket_ops::sync_recv1()
[2024-05-11 04:32:42,528 E 100618 100618] logging.cc:365:     @     0x7f664322b568        112  ray::ServerConnection::ReadBuffer()
[2024-05-11 04:32:42,528 E 100618 100618] logging.cc:365:     @     0x7f664322cb82        496  ray::ServerConnection::ReadMessage()
[2024-05-11 04:32:42,528 E 100618 100618] logging.cc:365:     @     0x7f6643062988        112  ray::raylet::RayletConnection::AtomicRequestReply()
[2024-05-11 04:32:42,528 E 100618 100618] logging.cc:365:     @     0x7f6643065b59        416  ray::raylet::RayletClient::RayletClient()
[2024-05-11 04:32:42,528 E 100618 100618] logging.cc:365:     @     0x7f6642fc043b       1248  ray::core::CoreWorker::CoreWorker()
[2024-05-11 04:32:42,528 E 100618 100618] logging.cc:365:     @     0x7f6642fc6791        624  ray::core::CoreWorkerProcessImpl::CoreWorkerProcessImpl()
[2024-05-11 04:32:42,528 E 100618 100618] logging.cc:365:     @     0x7f6642fc767f         80  ray::core::CoreWorkerProcess::Initialize()
[2024-05-11 04:32:42,528 E 100618 100618] logging.cc:365:     @     0x7f6642e86fdf       2016  __pyx_pw_3ray_7_raylet_10CoreWorker_1__cinit__()
[2024-05-11 04:32:42,528 E 100618 100618] logging.cc:365:     @     0x7f6642e88299         48  __pyx_tp_new_3ray_7_raylet_CoreWorker()
[2024-05-11 04:32:42,528 E 100618 100618] logging.cc:365:     @     0x55e532b0f9c7  (unknown)  _PyObject_MakeTpCall
[2024-05-11 04:32:42,530 E 100618 100618] logging.cc:365:     @     0x55e532f30ba0  (unknown)  (unknown)
