/mnt/hwfile/huqinghao/miniconda3/bin/python
2024-05-12 02:39:24,279 - INFO - Note: detected 128 virtual cores but NumExpr set to maximum of 64, check "NUMEXPR_MAX_THREADS" environment variable.
2024-05-12 02:39:24,279 - INFO - Note: NumExpr detected 128 cores but "NUMEXPR_MAX_THREADS" not set, so enforcing safe limit of 8.
2024-05-12 02:39:24,280 - INFO - NumExpr defaulting to 8 threads.
2024-05-12 02:39:25,621	INFO scripts.py:1182 -- Did not find any active Ray processes.
Waiting for 10 secs for the system to be ready: HTTPConnectionPool(host='localhost', port=8000): Max retries exceeded with url: /sysinfo (Caused by NewConnectionError('<urllib3.connection.HTTPConnection object at 0x7fc83cd78ac0>: Failed to establish a new connection: [Errno 111] Connection refused'))

==========
== CUDA ==
==========

CUDA Version 12.1.0

Container image Copyright (c) 2016-2023, NVIDIA CORPORATION & AFFILIATES. All rights reserved.

This container image and its contents are governed by the NVIDIA Deep Learning Container License.
By pulling and using the container, you accept the terms and conditions of this license:
https://developer.nvidia.com/ngc/nvidia-deep-learning-container-license

A copy of this license is made available in this container at /NGC-DL-CONTAINER-LICENSE for your convenience.

*************************
** DEPRECATION NOTICE! **
*************************
THIS IMAGE IS DEPRECATED and is scheduled for DELETION.
    https://gitlab.com/nvidia/container-images/cuda/blob/master/doc/support-policy.md

Waiting for 10 secs for the system to be ready: HTTPConnectionPool(host='localhost', port=8000): Max retries exceeded with url: /sysinfo (Caused by NewConnectionError('<urllib3.connection.HTTPConnection object at 0x7fc83cd79450>: Failed to establish a new connection: [Errno 111] Connection refused'))
/usr/local/lib/python3.10/dist-packages/pydantic/_internal/_fields.py:160: UserWarning: Field "model_name_or_path" has conflict with protected namespace "model_".

You may be able to resolve this warning by setting `model_config['protected_namespaces'] = ()`.
  warnings.warn(
INFO 05-12 02:39:42 api_server.py:212] vLLM API server version 0.3.3
INFO 05-12 02:39:42 api_server.py:213] args: Namespace(host=None, port=8000, uvicorn_log_level='info', allow_credentials=False, allowed_origins=['*'], allowed_methods=['*'], allowed_headers=['*'], api_key=None, served_model_name=None, lora_modules=[], delta_modules=[], swap_modules=[SwapModule(name='delta-1', local_path='/vllm/.idea/full_models/Llama-2-13b-hf-1'), SwapModule(name='delta-2', local_path='/vllm/.idea/full_models/Llama-2-13b-hf-2'), SwapModule(name='delta-3', local_path='/vllm/.idea/full_models/Llama-2-13b-hf-3'), SwapModule(name='delta-4', local_path='/vllm/.idea/full_models/Llama-2-13b-hf-4'), SwapModule(name='delta-5', local_path='/vllm/.idea/full_models/Llama-2-13b-hf-5'), SwapModule(name='delta-6', local_path='/vllm/.idea/full_models/Llama-2-13b-hf-6'), SwapModule(name='delta-7', local_path='/vllm/.idea/full_models/Llama-2-13b-hf-7'), SwapModule(name='delta-8', local_path='/vllm/.idea/full_models/Llama-2-13b-hf-8')], chat_template=None, response_role='assistant', ssl_keyfile=None, ssl_certfile=None, ssl_ca_certs=None, ssl_cert_reqs=0, root_path=None, middleware=[], model='/vllm/.idea/full_models/Llama-2-13b-hf', tokenizer=None, revision=None, code_revision=None, tokenizer_revision=None, tokenizer_mode='auto', trust_remote_code=False, download_dir=None, load_format='auto', dtype='auto', kv_cache_dtype='auto', max_model_len=None, worker_use_ray=False, pipeline_parallel_size=1, tensor_parallel_size=4, max_parallel_loading_workers=None, ray_workers_use_nsight=False, block_size=16, enable_prefix_caching=False, seed=0, swap_space=4, gpu_memory_utilization=0.85, max_num_batched_tokens=None, max_num_seqs=256, max_logprobs=5, disable_log_stats=False, quantization=None, enforce_eager=True, max_context_len_to_capture=8192, disable_custom_all_reduce=False, tokenizer_pool_size=0, tokenizer_pool_type='ray', tokenizer_pool_extra_config=None, enable_lora=False, max_loras=1, max_lora_rank=64, lora_extra_vocab_size=256, lora_dtype='auto', max_cpu_loras=32, enable_delta=False, max_deltas=0, max_cpu_deltas=32, max_delta_bitwidth=4, device='auto', image_input_type=None, image_token_id=None, image_input_shape=None, image_feature_size=None, scheduler_delay_factor=0.0, enable_prefetch=False, scheduler_policy='fcfs', engine_use_ray=False, disable_log_requests=True, max_log_len=None)
2024-05-12 02:39:46,021	INFO worker.py:1749 -- Started a local Ray instance.
Waiting for 10 secs for the system to be ready: HTTPConnectionPool(host='localhost', port=8000): Max retries exceeded with url: /sysinfo (Caused by NewConnectionError('<urllib3.connection.HTTPConnection object at 0x7fc83cd792d0>: Failed to establish a new connection: [Errno 111] Connection refused'))
INFO 05-12 02:39:48 llm_engine.py:87] Initializing an LLM engine (v0.3.3) with config: model='/vllm/.idea/full_models/Llama-2-13b-hf', tokenizer='/vllm/.idea/full_models/Llama-2-13b-hf', tokenizer_mode=auto, revision=None, tokenizer_revision=None, trust_remote_code=False, dtype=torch.float16, lora_config=None, delta_config=None, max_seq_len=4096, download_dir=None, load_format=auto, tensor_parallel_size=4, disable_custom_all_reduce=False, quantization=None, enforce_eager=True, kv_cache_dtype=auto, device_config=cuda, seed=0)
Waiting for 10 secs for the system to be ready: HTTPConnectionPool(host='localhost', port=8000): Max retries exceeded with url: /sysinfo (Caused by NewConnectionError('<urllib3.connection.HTTPConnection object at 0x7fc83cd782b0>: Failed to establish a new connection: [Errno 111] Connection refused'))
Waiting for 10 secs for the system to be ready: HTTPConnectionPool(host='localhost', port=8000): Max retries exceeded with url: /sysinfo (Caused by NewConnectionError('<urllib3.connection.HTTPConnection object at 0x7fc83cd79d20>: Failed to establish a new connection: [Errno 111] Connection refused'))
Waiting for 10 secs for the system to be ready: HTTPConnectionPool(host='localhost', port=8000): Max retries exceeded with url: /sysinfo (Caused by NewConnectionError('<urllib3.connection.HTTPConnection object at 0x7fc83cd7a5f0>: Failed to establish a new connection: [Errno 111] Connection refused'))
Waiting for 10 secs for the system to be ready: HTTPConnectionPool(host='localhost', port=8000): Max retries exceeded with url: /sysinfo (Caused by NewConnectionError('<urllib3.connection.HTTPConnection object at 0x7fc83cd7aec0>: Failed to establish a new connection: [Errno 111] Connection refused'))
Waiting for 10 secs for the system to be ready: HTTPConnectionPool(host='localhost', port=8000): Max retries exceeded with url: /sysinfo (Caused by NewConnectionError('<urllib3.connection.HTTPConnection object at 0x7fc83cd7ac80>: Failed to establish a new connection: [Errno 111] Connection refused'))
Waiting for 10 secs for the system to be ready: HTTPConnectionPool(host='localhost', port=8000): Max retries exceeded with url: /sysinfo (Caused by NewConnectionError('<urllib3.connection.HTTPConnection object at 0x7fc83cd7a3b0>: Failed to establish a new connection: [Errno 111] Connection refused'))
Waiting for 10 secs for the system to be ready: HTTPConnectionPool(host='localhost', port=8000): Max retries exceeded with url: /sysinfo (Caused by NewConnectionError('<urllib3.connection.HTTPConnection object at 0x7fc83cd79ae0>: Failed to establish a new connection: [Errno 111] Connection refused'))
Waiting for 10 secs for the system to be ready: HTTPConnectionPool(host='localhost', port=8000): Max retries exceeded with url: /sysinfo (Caused by NewConnectionError('<urllib3.connection.HTTPConnection object at 0x7fc83cd784f0>: Failed to establish a new connection: [Errno 111] Connection refused'))
Waiting for 10 secs for the system to be ready: HTTPConnectionPool(host='localhost', port=8000): Max retries exceeded with url: /sysinfo (Caused by NewConnectionError('<urllib3.connection.HTTPConnection object at 0x7fc83cd79480>: Failed to establish a new connection: [Errno 111] Connection refused'))
Waiting for 10 secs for the system to be ready: HTTPConnectionPool(host='localhost', port=8000): Max retries exceeded with url: /sysinfo (Caused by NewConnectionError('<urllib3.connection.HTTPConnection object at 0x7fc83cd78dc0>: Failed to establish a new connection: [Errno 111] Connection refused'))
Waiting for 10 secs for the system to be ready: HTTPConnectionPool(host='localhost', port=8000): Max retries exceeded with url: /sysinfo (Caused by NewConnectionError('<urllib3.connection.HTTPConnection object at 0x7fc83cd78610>: Failed to establish a new connection: [Errno 111] Connection refused'))
Waiting for 10 secs for the system to be ready: HTTPConnectionPool(host='localhost', port=8000): Max retries exceeded with url: /sysinfo (Caused by NewConnectionError('<urllib3.connection.HTTPConnection object at 0x7fc83cd7a200>: Failed to establish a new connection: [Errno 111] Connection refused'))
Waiting for 10 secs for the system to be ready: HTTPConnectionPool(host='localhost', port=8000): Max retries exceeded with url: /sysinfo (Caused by NewConnectionError('<urllib3.connection.HTTPConnection object at 0x7fc83cd7aad0>: Failed to establish a new connection: [Errno 111] Connection refused'))
Waiting for 10 secs for the system to be ready: HTTPConnectionPool(host='localhost', port=8000): Max retries exceeded with url: /sysinfo (Caused by NewConnectionError('<urllib3.connection.HTTPConnection object at 0x7fc83cd7af50>: Failed to establish a new connection: [Errno 111] Connection refused'))
Waiting for 10 secs for the system to be ready: HTTPConnectionPool(host='localhost', port=8000): Max retries exceeded with url: /sysinfo (Caused by NewConnectionError('<urllib3.connection.HTTPConnection object at 0x7fc83cd7b790>: Failed to establish a new connection: [Errno 111] Connection refused'))
Waiting for 10 secs for the system to be ready: HTTPConnectionPool(host='localhost', port=8000): Max retries exceeded with url: /sysinfo (Caused by NewConnectionError('<urllib3.connection.HTTPConnection object at 0x7fc83cd7ad10>: Failed to establish a new connection: [Errno 111] Connection refused'))
Waiting for 10 secs for the system to be ready: HTTPConnectionPool(host='localhost', port=8000): Max retries exceeded with url: /sysinfo (Caused by NewConnectionError('<urllib3.connection.HTTPConnection object at 0x7fc83cd79db0>: Failed to establish a new connection: [Errno 111] Connection refused'))
Waiting for 10 secs for the system to be ready: HTTPConnectionPool(host='localhost', port=8000): Max retries exceeded with url: /sysinfo (Caused by NewConnectionError('<urllib3.connection.HTTPConnection object at 0x7fc83cd78580>: Failed to establish a new connection: [Errno 111] Connection refused'))
Waiting for 10 secs for the system to be ready: HTTPConnectionPool(host='localhost', port=8000): Max retries exceeded with url: /sysinfo (Caused by NewConnectionError('<urllib3.connection.HTTPConnection object at 0x7fc83cd79300>: Failed to establish a new connection: [Errno 111] Connection refused'))
Waiting for 10 secs for the system to be ready: HTTPConnectionPool(host='localhost', port=8000): Max retries exceeded with url: /sysinfo (Caused by NewConnectionError('<urllib3.connection.HTTPConnection object at 0x7fc83cd794e0>: Failed to establish a new connection: [Errno 111] Connection refused'))
Waiting for 10 secs for the system to be ready: HTTPConnectionPool(host='localhost', port=8000): Max retries exceeded with url: /sysinfo (Caused by NewConnectionError('<urllib3.connection.HTTPConnection object at 0x7fc83cd78e80>: Failed to establish a new connection: [Errno 111] Connection refused'))
Waiting for 10 secs for the system to be ready: HTTPConnectionPool(host='localhost', port=8000): Max retries exceeded with url: /sysinfo (Caused by NewConnectionError('<urllib3.connection.HTTPConnection object at 0x7fc83cd78250>: Failed to establish a new connection: [Errno 111] Connection refused'))
Waiting for 10 secs for the system to be ready: HTTPConnectionPool(host='localhost', port=8000): Max retries exceeded with url: /sysinfo (Caused by NewConnectionError('<urllib3.connection.HTTPConnection object at 0x7fc83cd799f0>: Failed to establish a new connection: [Errno 111] Connection refused'))
Waiting for 10 secs for the system to be ready: HTTPConnectionPool(host='localhost', port=8000): Max retries exceeded with url: /sysinfo (Caused by NewConnectionError('<urllib3.connection.HTTPConnection object at 0x7fc83cd7a2c0>: Failed to establish a new connection: [Errno 111] Connection refused'))
Waiting for 10 secs for the system to be ready: HTTPConnectionPool(host='localhost', port=8000): Max retries exceeded with url: /sysinfo (Caused by NewConnectionError('<urllib3.connection.HTTPConnection object at 0x7fc83cd7b130>: Failed to establish a new connection: [Errno 111] Connection refused'))
Waiting for 10 secs for the system to be ready: HTTPConnectionPool(host='localhost', port=8000): Max retries exceeded with url: /sysinfo (Caused by NewConnectionError('<urllib3.connection.HTTPConnection object at 0x7fc83cd7b7f0>: Failed to establish a new connection: [Errno 111] Connection refused'))
Waiting for 10 secs for the system to be ready: HTTPConnectionPool(host='localhost', port=8000): Max retries exceeded with url: /sysinfo (Caused by NewConnectionError('<urllib3.connection.HTTPConnection object at 0x7fc83cd7b610>: Failed to establish a new connection: [Errno 111] Connection refused'))
Waiting for 10 secs for the system to be ready: HTTPConnectionPool(host='localhost', port=8000): Max retries exceeded with url: /sysinfo (Caused by NewConnectionError('<urllib3.connection.HTTPConnection object at 0x7fc83cd7b820>: Failed to establish a new connection: [Errno 111] Connection refused'))
Waiting for 10 secs for the system to be ready: HTTPConnectionPool(host='localhost', port=8000): Max retries exceeded with url: /sysinfo (Caused by NewConnectionError('<urllib3.connection.HTTPConnection object at 0x7fc83cd7aef0>: Failed to establish a new connection: [Errno 111] Connection refused'))
Waiting for 10 secs for the system to be ready: HTTPConnectionPool(host='localhost', port=8000): Max retries exceeded with url: /sysinfo (Caused by NewConnectionError('<urllib3.connection.HTTPConnection object at 0x7fc83cd7a6e0>: Failed to establish a new connection: [Errno 111] Connection refused'))
Waiting for 10 secs for the system to be ready: HTTPConnectionPool(host='localhost', port=8000): Max retries exceeded with url: /sysinfo (Caused by NewConnectionError('<urllib3.connection.HTTPConnection object at 0x7fc83cd79e10>: Failed to establish a new connection: [Errno 111] Connection refused'))
Waiting for 10 secs for the system to be ready: HTTPConnectionPool(host='localhost', port=8000): Max retries exceeded with url: /sysinfo (Caused by NewConnectionError('<urllib3.connection.HTTPConnection object at 0x7fc83cd7b670>: Failed to establish a new connection: [Errno 111] Connection refused'))
Waiting for 10 secs for the system to be ready: HTTPConnectionPool(host='localhost', port=8000): Max retries exceeded with url: /sysinfo (Caused by NewConnectionError('<urllib3.connection.HTTPConnection object at 0x7fc83cd78910>: Failed to establish a new connection: [Errno 111] Connection refused'))
Waiting for 10 secs for the system to be ready: HTTPConnectionPool(host='localhost', port=8000): Max retries exceeded with url: /sysinfo (Caused by NewConnectionError('<urllib3.connection.HTTPConnection object at 0x7fc83cd7a140>: Failed to establish a new connection: [Errno 111] Connection refused'))
Waiting for 10 secs for the system to be ready: HTTPConnectionPool(host='localhost', port=8000): Max retries exceeded with url: /sysinfo (Caused by NewConnectionError('<urllib3.connection.HTTPConnection object at 0x7fc83cd7b340>: Failed to establish a new connection: [Errno 111] Connection refused'))
Waiting for 10 secs for the system to be ready: HTTPConnectionPool(host='localhost', port=8000): Max retries exceeded with url: /sysinfo (Caused by NewConnectionError('<urllib3.connection.HTTPConnection object at 0x7fc83cd7abf0>: Failed to establish a new connection: [Errno 111] Connection refused'))
Waiting for 10 secs for the system to be ready: HTTPConnectionPool(host='localhost', port=8000): Max retries exceeded with url: /sysinfo (Caused by NewConnectionError('<urllib3.connection.HTTPConnection object at 0x7fc83cd7bc70>: Failed to establish a new connection: [Errno 111] Connection refused'))
Waiting for 10 secs for the system to be ready: HTTPConnectionPool(host='localhost', port=8000): Max retries exceeded with url: /sysinfo (Caused by NewConnectionError('<urllib3.connection.HTTPConnection object at 0x7fc83cd7b4c0>: Failed to establish a new connection: [Errno 111] Connection refused'))
Waiting for 10 secs for the system to be ready: HTTPConnectionPool(host='localhost', port=8000): Max retries exceeded with url: /sysinfo (Caused by NewConnectionError('<urllib3.connection.HTTPConnection object at 0x7fc83cd79840>: Failed to establish a new connection: [Errno 111] Connection refused'))
Waiting for 10 secs for the system to be ready: HTTPConnectionPool(host='localhost', port=8000): Max retries exceeded with url: /sysinfo (Caused by NewConnectionError('<urllib3.connection.HTTPConnection object at 0x7fc83cd7ae00>: Failed to establish a new connection: [Errno 111] Connection refused'))
Waiting for 10 secs for the system to be ready: HTTPConnectionPool(host='localhost', port=8000): Max retries exceeded with url: /sysinfo (Caused by NewConnectionError('<urllib3.connection.HTTPConnection object at 0x7fc83cd7aa70>: Failed to establish a new connection: [Errno 111] Connection refused'))
Waiting for 10 secs for the system to be ready: HTTPConnectionPool(host='localhost', port=8000): Max retries exceeded with url: /sysinfo (Caused by NewConnectionError('<urllib3.connection.HTTPConnection object at 0x7fc83cd7a1a0>: Failed to establish a new connection: [Errno 111] Connection refused'))
Waiting for 10 secs for the system to be ready: HTTPConnectionPool(host='localhost', port=8000): Max retries exceeded with url: /sysinfo (Caused by NewConnectionError('<urllib3.connection.HTTPConnection object at 0x7fc83c9700a0>: Failed to establish a new connection: [Errno 111] Connection refused'))
Waiting for 10 secs for the system to be ready: HTTPConnectionPool(host='localhost', port=8000): Max retries exceeded with url: /sysinfo (Caused by NewConnectionError('<urllib3.connection.HTTPConnection object at 0x7fc83cd7a620>: Failed to establish a new connection: [Errno 111] Connection refused'))
Waiting for 10 secs for the system to be ready: HTTPConnectionPool(host='localhost', port=8000): Max retries exceeded with url: /sysinfo (Caused by NewConnectionError('<urllib3.connection.HTTPConnection object at 0x7fc83cd7b070>: Failed to establish a new connection: [Errno 111] Connection refused'))
Waiting for 10 secs for the system to be ready: HTTPConnectionPool(host='localhost', port=8000): Max retries exceeded with url: /sysinfo (Caused by NewConnectionError('<urllib3.connection.HTTPConnection object at 0x7fc83cd7ba60>: Failed to establish a new connection: [Errno 111] Connection refused'))
Waiting for 10 secs for the system to be ready: HTTPConnectionPool(host='localhost', port=8000): Max retries exceeded with url: /sysinfo (Caused by NewConnectionError('<urllib3.connection.HTTPConnection object at 0x7fc83cd7ad10>: Failed to establish a new connection: [Errno 111] Connection refused'))
Waiting for 10 secs for the system to be ready: HTTPConnectionPool(host='localhost', port=8000): Max retries exceeded with url: /sysinfo (Caused by NewConnectionError('<urllib3.connection.HTTPConnection object at 0x7fc83cd792d0>: Failed to establish a new connection: [Errno 111] Connection refused'))
Waiting for 10 secs for the system to be ready: HTTPConnectionPool(host='localhost', port=8000): Max retries exceeded with url: /sysinfo (Caused by NewConnectionError('<urllib3.connection.HTTPConnection object at 0x7fc83cd7b4c0>: Failed to establish a new connection: [Errno 111] Connection refused'))
Waiting for 10 secs for the system to be ready: HTTPConnectionPool(host='localhost', port=8000): Max retries exceeded with url: /sysinfo (Caused by NewConnectionError('<urllib3.connection.HTTPConnection object at 0x7fc83cd7bb20>: Failed to establish a new connection: [Errno 111] Connection refused'))
Waiting for 10 secs for the system to be ready: HTTPConnectionPool(host='localhost', port=8000): Max retries exceeded with url: /sysinfo (Caused by NewConnectionError('<urllib3.connection.HTTPConnection object at 0x7fc83cd7ada0>: Failed to establish a new connection: [Errno 111] Connection refused'))
Waiting for 10 secs for the system to be ready: HTTPConnectionPool(host='localhost', port=8000): Max retries exceeded with url: /sysinfo (Caused by NewConnectionError('<urllib3.connection.HTTPConnection object at 0x7fc83cd7a980>: Failed to establish a new connection: [Errno 111] Connection refused'))
Waiting for 10 secs for the system to be ready: HTTPConnectionPool(host='localhost', port=8000): Max retries exceeded with url: /sysinfo (Caused by NewConnectionError('<urllib3.connection.HTTPConnection object at 0x7fc83cd7a0b0>: Failed to establish a new connection: [Errno 111] Connection refused'))
Waiting for 10 secs for the system to be ready: HTTPConnectionPool(host='localhost', port=8000): Max retries exceeded with url: /sysinfo (Caused by NewConnectionError('<urllib3.connection.HTTPConnection object at 0x7fc83cd786a0>: Failed to establish a new connection: [Errno 111] Connection refused'))
Waiting for 10 secs for the system to be ready: HTTPConnectionPool(host='localhost', port=8000): Max retries exceeded with url: /sysinfo (Caused by NewConnectionError('<urllib3.connection.HTTPConnection object at 0x7fc83cd7a0e0>: Failed to establish a new connection: [Errno 111] Connection refused'))
Waiting for 10 secs for the system to be ready: HTTPConnectionPool(host='localhost', port=8000): Max retries exceeded with url: /sysinfo (Caused by NewConnectionError('<urllib3.connection.HTTPConnection object at 0x7fc83cd7ab90>: Failed to establish a new connection: [Errno 111] Connection refused'))
Waiting for 10 secs for the system to be ready: HTTPConnectionPool(host='localhost', port=8000): Max retries exceeded with url: /sysinfo (Caused by NewConnectionError('<urllib3.connection.HTTPConnection object at 0x7fc83cd7b6a0>: Failed to establish a new connection: [Errno 111] Connection refused'))
INFO 05-12 02:49:25 selector.py:16] Using FlashAttention backend.
Waiting for 10 secs for the system to be ready: HTTPConnectionPool(host='localhost', port=8000): Max retries exceeded with url: /sysinfo (Caused by NewConnectionError('<urllib3.connection.HTTPConnection object at 0x7fc83cd7b880>: Failed to establish a new connection: [Errno 111] Connection refused'))
[36m(RayWorkerVllm pid=19313)[0m Exception ignored in: <function TempDirectory.__del__ at 0x7fc4871c0ee0>
[36m(RayWorkerVllm pid=19313)[0m Traceback (most recent call last):
[36m(RayWorkerVllm pid=19313)[0m   File "/usr/local/lib/python3.10/dist-packages/bitblas/3rdparty/tvm/python/tvm/contrib/utils.py", line 145, in __del__
[36m(RayWorkerVllm pid=19313)[0m     self.remove()
[36m(RayWorkerVllm pid=19313)[0m   File "/usr/local/lib/python3.10/dist-packages/bitblas/3rdparty/tvm/python/tvm/contrib/utils.py", line 121, in remove
[36m(RayWorkerVllm pid=19313)[0m     if self.temp_dir:
[36m(RayWorkerVllm pid=19313)[0m AttributeError: 'TempDirectory' object has no attribute 'temp_dir'
[36m(RayWorkerVllm pid=19684)[0m Exception ignored in: <function TempDirectory.__del__ at 0x7f58b4038ee0>
[36m(RayWorkerVllm pid=19684)[0m Traceback (most recent call last):
[36m(RayWorkerVllm pid=19684)[0m   File "/usr/local/lib/python3.10/dist-packages/bitblas/3rdparty/tvm/python/tvm/contrib/utils.py", line 145, in __del__
[36m(RayWorkerVllm pid=19684)[0m     self.remove()
[36m(RayWorkerVllm pid=19684)[0m   File "/usr/local/lib/python3.10/dist-packages/bitblas/3rdparty/tvm/python/tvm/contrib/utils.py", line 121, in remove
[36m(RayWorkerVllm pid=19684)[0m     if self.temp_dir:
[36m(RayWorkerVllm pid=19684)[0m AttributeError: 'TempDirectory' object has no attribute 'temp_dir'
Waiting for 10 secs for the system to be ready: HTTPConnectionPool(host='localhost', port=8000): Max retries exceeded with url: /sysinfo (Caused by NewConnectionError('<urllib3.connection.HTTPConnection object at 0x7fc83c970520>: Failed to establish a new connection: [Errno 111] Connection refused'))
[36m(RayWorkerVllm pid=19684)[0m Exception ignored in: <function TempDirectory.__del__ at 0x7f58b4038ee0>
[36m(RayWorkerVllm pid=19684)[0m Traceback (most recent call last):
[36m(RayWorkerVllm pid=19684)[0m   File "/usr/local/lib/python3.10/dist-packages/bitblas/3rdparty/tvm/python/tvm/contrib/utils.py", line 145, in __del__
[36m(RayWorkerVllm pid=19684)[0m     self.remove()
[36m(RayWorkerVllm pid=19684)[0m   File "/usr/local/lib/python3.10/dist-packages/bitblas/3rdparty/tvm/python/tvm/contrib/utils.py", line 121, in remove
[36m(RayWorkerVllm pid=19684)[0m     if self.temp_dir:
[36m(RayWorkerVllm pid=19684)[0m AttributeError: 'TempDirectory' object has no attribute 'temp_dir'
Waiting for 10 secs for the system to be ready: HTTPConnectionPool(host='localhost', port=8000): Max retries exceeded with url: /sysinfo (Caused by NewConnectionError('<urllib3.connection.HTTPConnection object at 0x7fc83cd79720>: Failed to establish a new connection: [Errno 111] Connection refused'))
Waiting for 10 secs for the system to be ready: HTTPConnectionPool(host='localhost', port=8000): Max retries exceeded with url: /sysinfo (Caused by NewConnectionError('<urllib3.connection.HTTPConnection object at 0x7fc83cd7be50>: Failed to establish a new connection: [Errno 111] Connection refused'))
Waiting for 10 secs for the system to be ready: HTTPConnectionPool(host='localhost', port=8000): Max retries exceeded with url: /sysinfo (Caused by NewConnectionError('<urllib3.connection.HTTPConnection object at 0x7fc83cd7bbb0>: Failed to establish a new connection: [Errno 111] Connection refused'))
Waiting for 10 secs for the system to be ready: HTTPConnectionPool(host='localhost', port=8000): Max retries exceeded with url: /sysinfo (Caused by NewConnectionError('<urllib3.connection.HTTPConnection object at 0x7fc83cd7a7a0>: Failed to establish a new connection: [Errno 111] Connection refused'))
Waiting for 10 secs for the system to be ready: HTTPConnectionPool(host='localhost', port=8000): Max retries exceeded with url: /sysinfo (Caused by NewConnectionError('<urllib3.connection.HTTPConnection object at 0x7fc83cd79ed0>: Failed to establish a new connection: [Errno 111] Connection refused'))
Waiting for 10 secs for the system to be ready: HTTPConnectionPool(host='localhost', port=8000): Max retries exceeded with url: /sysinfo (Caused by NewConnectionError('<urllib3.connection.HTTPConnection object at 0x7fc83c9709a0>: Failed to establish a new connection: [Errno 111] Connection refused'))
Waiting for 10 secs for the system to be ready: HTTPConnectionPool(host='localhost', port=8000): Max retries exceeded with url: /sysinfo (Caused by NewConnectionError('<urllib3.connection.HTTPConnection object at 0x7fc83cd7a410>: Failed to establish a new connection: [Errno 111] Connection refused'))
Waiting for 10 secs for the system to be ready: HTTPConnectionPool(host='localhost', port=8000): Max retries exceeded with url: /sysinfo (Caused by NewConnectionError('<urllib3.connection.HTTPConnection object at 0x7fc83cd7b0a0>: Failed to establish a new connection: [Errno 111] Connection refused'))
Waiting for 10 secs for the system to be ready: HTTPConnectionPool(host='localhost', port=8000): Max retries exceeded with url: /sysinfo (Caused by NewConnectionError('<urllib3.connection.HTTPConnection object at 0x7fc83cd7bc40>: Failed to establish a new connection: [Errno 111] Connection refused'))
Waiting for 10 secs for the system to be ready: HTTPConnectionPool(host='localhost', port=8000): Max retries exceeded with url: /sysinfo (Caused by NewConnectionError('<urllib3.connection.HTTPConnection object at 0x7fc83cd78dc0>: Failed to establish a new connection: [Errno 111] Connection refused'))
Waiting for 10 secs for the system to be ready: HTTPConnectionPool(host='localhost', port=8000): Max retries exceeded with url: /sysinfo (Caused by NewConnectionError('<urllib3.connection.HTTPConnection object at 0x7fc83c970340>: Failed to establish a new connection: [Errno 111] Connection refused'))
Waiting for 10 secs for the system to be ready: HTTPConnectionPool(host='localhost', port=8000): Max retries exceeded with url: /sysinfo (Caused by NewConnectionError('<urllib3.connection.HTTPConnection object at 0x7fc83cd79720>: Failed to establish a new connection: [Errno 111] Connection refused'))
slurmstepd: error: *** JOB 3671323 ON HOST-10-140-60-2 CANCELLED AT 2024-05-12T02:51:46 ***
[failure_signal_handler.cc : 332] RAW: Signal 15 raised at PC=0x7fba9e1e37a2 while already in AbslFailureSignalHandler()
*** SIGTERM received at time=1715453506 on cpu 58 ***
PC: @     0x7fba9e1e37a2  (unknown)  (unknown)
    @     0x7fba9e074520       4752  (unknown)
    @     0x7fb9eeede280  (unknown)  (unknown)
[2024-05-12 02:51:46,163 E 11608 11608] logging.cc:365: *** SIGTERM received at time=1715453506 on cpu 58 ***
[2024-05-12 02:51:46,172 E 11608 11608] logging.cc:365: PC: @     0x7fba9e1e37a2  (unknown)  (unknown)
[2024-05-12 02:51:46,172 E 11608 11608] logging.cc:365:     @     0x7fba9e074520       4752  (unknown)
[2024-05-12 02:51:46,181 E 11608 11608] logging.cc:365:     @     0x7fb9eeede280  (unknown)  (unknown)
*** SIGTERM received at time=1715453506 on cpu 58 ***
PC: @     0x7fba9e1177f8  (unknown)  clock_nanosleep
    @     0x7fba9e074520  (unknown)  (unknown)
    @ ... and at least 3 more frames
[2024-05-12 02:51:46,189 E 11608 11608] logging.cc:365: *** SIGTERM received at time=1715453506 on cpu 58 ***
[2024-05-12 02:51:46,189 E 11608 11608] logging.cc:365: PC: @     0x7fba9e1177f8  (unknown)  clock_nanosleep
[2024-05-12 02:51:46,189 E 11608 11608] logging.cc:365:     @     0x7fba9e074520  (unknown)  (unknown)
[2024-05-12 02:51:46,189 E 11608 11608] logging.cc:365:     @ ... and at least 3 more frames
