/mnt/hwfile/huqinghao/miniconda3/bin/python
2024-05-13 03:30:16,174 - INFO - Note: detected 128 virtual cores but NumExpr set to maximum of 64, check "NUMEXPR_MAX_THREADS" environment variable.
2024-05-13 03:30:16,175 - INFO - Note: NumExpr detected 128 cores but "NUMEXPR_MAX_THREADS" not set, so enforcing safe limit of 8.
2024-05-13 03:30:16,175 - INFO - NumExpr defaulting to 8 threads.
2024-05-13 03:30:17,796	INFO scripts.py:1182 -- Did not find any active Ray processes.

==========
== CUDA ==
==========

CUDA Version 12.1.0

Container image Copyright (c) 2016-2023, NVIDIA CORPORATION & AFFILIATES. All rights reserved.

This container image and its contents are governed by the NVIDIA Deep Learning Container License.
By pulling and using the container, you accept the terms and conditions of this license:
https://developer.nvidia.com/ngc/nvidia-deep-learning-container-license

A copy of this license is made available in this container at /NGC-DL-CONTAINER-LICENSE for your convenience.

*************************
** DEPRECATION NOTICE! **
*************************
THIS IMAGE IS DEPRECATED and is scheduled for DELETION.
    https://gitlab.com/nvidia/container-images/cuda/blob/master/doc/support-policy.md

Waiting for 10 secs for the system to be ready: HTTPConnectionPool(host='localhost', port=8000): Max retries exceeded with url: /sysinfo (Caused by NewConnectionError('<urllib3.connection.HTTPConnection object at 0x7fdd289e8460>: Failed to establish a new connection: [Errno 111] Connection refused'))
Waiting for 10 secs for the system to be ready: HTTPConnectionPool(host='localhost', port=8000): Max retries exceeded with url: /sysinfo (Caused by NewConnectionError('<urllib3.connection.HTTPConnection object at 0x7fdd289e8d30>: Failed to establish a new connection: [Errno 111] Connection refused'))
INFO 05-13 03:30:30 api_server.py:210] vLLM API server version 0.3.3
INFO 05-13 03:30:30 api_server.py:211] args: Namespace(host=None, port=8000, uvicorn_log_level='info', allow_credentials=False, allowed_origins=['*'], allowed_methods=['*'], allowed_headers=['*'], api_key=None, served_model_name=None, lora_modules=[], delta_modules=[], swap_modules=[SwapModule(name='delta-1', local_path='/vllm/.idea/full_models/Llama-2-13b-hf-1'), SwapModule(name='delta-2', local_path='/vllm/.idea/full_models/Llama-2-13b-hf-2'), SwapModule(name='delta-3', local_path='/vllm/.idea/full_models/Llama-2-13b-hf-3'), SwapModule(name='delta-4', local_path='/vllm/.idea/full_models/Llama-2-13b-hf-4'), SwapModule(name='delta-5', local_path='/vllm/.idea/full_models/Llama-2-13b-hf-5'), SwapModule(name='delta-6', local_path='/vllm/.idea/full_models/Llama-2-13b-hf-6'), SwapModule(name='delta-7', local_path='/vllm/.idea/full_models/Llama-2-13b-hf-7'), SwapModule(name='delta-8', local_path='/vllm/.idea/full_models/Llama-2-13b-hf-8')], chat_template=None, response_role='assistant', ssl_keyfile=None, ssl_certfile=None, ssl_ca_certs=None, ssl_cert_reqs=0, root_path=None, middleware=[], model='/vllm/.idea/full_models/Llama-2-13b-hf', tokenizer=None, revision=None, code_revision=None, tokenizer_revision=None, tokenizer_mode='auto', trust_remote_code=False, download_dir=None, load_format='auto', dtype='auto', kv_cache_dtype='auto', max_model_len=None, worker_use_ray=False, pipeline_parallel_size=1, tensor_parallel_size=4, max_parallel_loading_workers=None, ray_workers_use_nsight=False, block_size=16, enable_prefix_caching=False, seed=0, swap_space=4, gpu_memory_utilization=0.85, max_num_batched_tokens=None, max_num_seqs=256, max_logprobs=5, disable_log_stats=False, quantization=None, enforce_eager=True, max_context_len_to_capture=8192, disable_custom_all_reduce=False, tokenizer_pool_size=0, tokenizer_pool_type='ray', tokenizer_pool_extra_config=None, enable_lora=False, max_loras=1, max_lora_rank=64, lora_extra_vocab_size=256, lora_dtype='auto', max_cpu_loras=32, enable_delta=False, max_deltas=0, max_cpu_deltas=32, max_delta_bitwidth=4, device='auto', image_input_type=None, image_token_id=None, image_input_shape=None, image_feature_size=None, scheduler_delay_factor=0.0, enable_prefetch=False, scheduler_policy='fcfs', engine_use_ray=False, disable_log_requests=True, max_log_len=None)
2024-05-13 03:30:34,148	INFO worker.py:1749 -- Started a local Ray instance.
INFO 05-13 03:30:36 llm_engine.py:87] Initializing an LLM engine (v0.3.3) with config: model='/vllm/.idea/full_models/Llama-2-13b-hf', tokenizer='/vllm/.idea/full_models/Llama-2-13b-hf', tokenizer_mode=auto, revision=None, tokenizer_revision=None, trust_remote_code=False, dtype=torch.float16, lora_config=None, delta_config=None, max_seq_len=4096, download_dir=None, load_format=auto, tensor_parallel_size=4, disable_custom_all_reduce=False, quantization=None, enforce_eager=True, kv_cache_dtype=auto, device_config=cuda, seed=0)
Waiting for 10 secs for the system to be ready: HTTPConnectionPool(host='localhost', port=8000): Max retries exceeded with url: /sysinfo (Caused by NewConnectionError('<urllib3.connection.HTTPConnection object at 0x7fdd28df3f70>: Failed to establish a new connection: [Errno 111] Connection refused'))
Waiting for 10 secs for the system to be ready: HTTPConnectionPool(host='localhost', port=8000): Max retries exceeded with url: /sysinfo (Caused by NewConnectionError('<urllib3.connection.HTTPConnection object at 0x7fdd289e86a0>: Failed to establish a new connection: [Errno 111] Connection refused'))
Waiting for 10 secs for the system to be ready: HTTPConnectionPool(host='localhost', port=8000): Max retries exceeded with url: /sysinfo (Caused by NewConnectionError('<urllib3.connection.HTTPConnection object at 0x7fdd289e95a0>: Failed to establish a new connection: [Errno 111] Connection refused'))
Waiting for 10 secs for the system to be ready: HTTPConnectionPool(host='localhost', port=8000): Max retries exceeded with url: /sysinfo (Caused by NewConnectionError('<urllib3.connection.HTTPConnection object at 0x7fdd289e9e10>: Failed to establish a new connection: [Errno 111] Connection refused'))
Waiting for 10 secs for the system to be ready: HTTPConnectionPool(host='localhost', port=8000): Max retries exceeded with url: /sysinfo (Caused by NewConnectionError('<urllib3.connection.HTTPConnection object at 0x7fdd289ea680>: Failed to establish a new connection: [Errno 111] Connection refused'))
Waiting for 10 secs for the system to be ready: HTTPConnectionPool(host='localhost', port=8000): Max retries exceeded with url: /sysinfo (Caused by NewConnectionError('<urllib3.connection.HTTPConnection object at 0x7fdd289e9ea0>: Failed to establish a new connection: [Errno 111] Connection refused'))
Waiting for 10 secs for the system to be ready: HTTPConnectionPool(host='localhost', port=8000): Max retries exceeded with url: /sysinfo (Caused by NewConnectionError('<urllib3.connection.HTTPConnection object at 0x7fdd289e9630>: Failed to establish a new connection: [Errno 111] Connection refused'))
Waiting for 10 secs for the system to be ready: HTTPConnectionPool(host='localhost', port=8000): Max retries exceeded with url: /sysinfo (Caused by NewConnectionError('<urllib3.connection.HTTPConnection object at 0x7fdd289e8610>: Failed to establish a new connection: [Errno 111] Connection refused'))
Waiting for 10 secs for the system to be ready: HTTPConnectionPool(host='localhost', port=8000): Max retries exceeded with url: /sysinfo (Caused by NewConnectionError('<urllib3.connection.HTTPConnection object at 0x7fdd289e89a0>: Failed to establish a new connection: [Errno 111] Connection refused'))
Waiting for 10 secs for the system to be ready: HTTPConnectionPool(host='localhost', port=8000): Max retries exceeded with url: /sysinfo (Caused by NewConnectionError('<urllib3.connection.HTTPConnection object at 0x7fdd289e8dc0>: Failed to establish a new connection: [Errno 111] Connection refused'))
Waiting for 10 secs for the system to be ready: HTTPConnectionPool(host='localhost', port=8000): Max retries exceeded with url: /sysinfo (Caused by NewConnectionError('<urllib3.connection.HTTPConnection object at 0x7fdd28df3c40>: Failed to establish a new connection: [Errno 111] Connection refused'))
Waiting for 10 secs for the system to be ready: HTTPConnectionPool(host='localhost', port=8000): Max retries exceeded with url: /sysinfo (Caused by NewConnectionError('<urllib3.connection.HTTPConnection object at 0x7fdd289e8be0>: Failed to establish a new connection: [Errno 111] Connection refused'))
Waiting for 10 secs for the system to be ready: HTTPConnectionPool(host='localhost', port=8000): Max retries exceeded with url: /sysinfo (Caused by NewConnectionError('<urllib3.connection.HTTPConnection object at 0x7fdd289e91b0>: Failed to establish a new connection: [Errno 111] Connection refused'))
Waiting for 10 secs for the system to be ready: HTTPConnectionPool(host='localhost', port=8000): Max retries exceeded with url: /sysinfo (Caused by NewConnectionError('<urllib3.connection.HTTPConnection object at 0x7fdd289e9a20>: Failed to establish a new connection: [Errno 111] Connection refused'))
Waiting for 10 secs for the system to be ready: HTTPConnectionPool(host='localhost', port=8000): Max retries exceeded with url: /sysinfo (Caused by NewConnectionError('<urllib3.connection.HTTPConnection object at 0x7fdd289ea290>: Failed to establish a new connection: [Errno 111] Connection refused'))
Waiting for 10 secs for the system to be ready: HTTPConnectionPool(host='localhost', port=8000): Max retries exceeded with url: /sysinfo (Caused by NewConnectionError('<urllib3.connection.HTTPConnection object at 0x7fdd289eaf50>: Failed to establish a new connection: [Errno 111] Connection refused'))
Waiting for 10 secs for the system to be ready: HTTPConnectionPool(host='localhost', port=8000): Max retries exceeded with url: /sysinfo (Caused by NewConnectionError('<urllib3.connection.HTTPConnection object at 0x7fdd289ea230>: Failed to establish a new connection: [Errno 111] Connection refused'))
Waiting for 10 secs for the system to be ready: HTTPConnectionPool(host='localhost', port=8000): Max retries exceeded with url: /sysinfo (Caused by NewConnectionError('<urllib3.connection.HTTPConnection object at 0x7fdd289e99c0>: Failed to establish a new connection: [Errno 111] Connection refused'))
Waiting for 10 secs for the system to be ready: HTTPConnectionPool(host='localhost', port=8000): Max retries exceeded with url: /sysinfo (Caused by NewConnectionError('<urllib3.connection.HTTPConnection object at 0x7fdd289e9150>: Failed to establish a new connection: [Errno 111] Connection refused'))
Waiting for 10 secs for the system to be ready: HTTPConnectionPool(host='localhost', port=8000): Max retries exceeded with url: /sysinfo (Caused by NewConnectionError('<urllib3.connection.HTTPConnection object at 0x7fdd289e8c10>: Failed to establish a new connection: [Errno 111] Connection refused'))
Waiting for 10 secs for the system to be ready: HTTPConnectionPool(host='localhost', port=8000): Max retries exceeded with url: /sysinfo (Caused by NewConnectionError('<urllib3.connection.HTTPConnection object at 0x7fdd289e8a60>: Failed to establish a new connection: [Errno 111] Connection refused'))
Waiting for 10 secs for the system to be ready: HTTPConnectionPool(host='localhost', port=8000): Max retries exceeded with url: /sysinfo (Caused by NewConnectionError('<urllib3.connection.HTTPConnection object at 0x7fdd28df3af0>: Failed to establish a new connection: [Errno 111] Connection refused'))
Waiting for 10 secs for the system to be ready: HTTPConnectionPool(host='localhost', port=8000): Max retries exceeded with url: /sysinfo (Caused by NewConnectionError('<urllib3.connection.HTTPConnection object at 0x7fdd289e8580>: Failed to establish a new connection: [Errno 111] Connection refused'))
Waiting for 10 secs for the system to be ready: HTTPConnectionPool(host='localhost', port=8000): Max retries exceeded with url: /sysinfo (Caused by NewConnectionError('<urllib3.connection.HTTPConnection object at 0x7fdd289e9600>: Failed to establish a new connection: [Errno 111] Connection refused'))
Waiting for 10 secs for the system to be ready: HTTPConnectionPool(host='localhost', port=8000): Max retries exceeded with url: /sysinfo (Caused by NewConnectionError('<urllib3.connection.HTTPConnection object at 0x7fdd289e9e70>: Failed to establish a new connection: [Errno 111] Connection refused'))
Waiting for 10 secs for the system to be ready: HTTPConnectionPool(host='localhost', port=8000): Max retries exceeded with url: /sysinfo (Caused by NewConnectionError('<urllib3.connection.HTTPConnection object at 0x7fdd289ea6e0>: Failed to establish a new connection: [Errno 111] Connection refused'))
Waiting for 10 secs for the system to be ready: HTTPConnectionPool(host='localhost', port=8000): Max retries exceeded with url: /sysinfo (Caused by NewConnectionError('<urllib3.connection.HTTPConnection object at 0x7fdd289e9000>: Failed to establish a new connection: [Errno 111] Connection refused'))
Waiting for 10 secs for the system to be ready: HTTPConnectionPool(host='localhost', port=8000): Max retries exceeded with url: /sysinfo (Caused by NewConnectionError('<urllib3.connection.HTTPConnection object at 0x7fdd28df3f10>: Failed to establish a new connection: [Errno 111] Connection refused'))
Waiting for 10 secs for the system to be ready: HTTPConnectionPool(host='localhost', port=8000): Max retries exceeded with url: /sysinfo (Caused by NewConnectionError('<urllib3.connection.HTTPConnection object at 0x7fdd289eaf80>: Failed to establish a new connection: [Errno 111] Connection refused'))
Waiting for 10 secs for the system to be ready: HTTPConnectionPool(host='localhost', port=8000): Max retries exceeded with url: /sysinfo (Caused by NewConnectionError('<urllib3.connection.HTTPConnection object at 0x7fdd289ea380>: Failed to establish a new connection: [Errno 111] Connection refused'))
Waiting for 10 secs for the system to be ready: HTTPConnectionPool(host='localhost', port=8000): Max retries exceeded with url: /sysinfo (Caused by NewConnectionError('<urllib3.connection.HTTPConnection object at 0x7fdd289e9b10>: Failed to establish a new connection: [Errno 111] Connection refused'))
Waiting for 10 secs for the system to be ready: HTTPConnectionPool(host='localhost', port=8000): Max retries exceeded with url: /sysinfo (Caused by NewConnectionError('<urllib3.connection.HTTPConnection object at 0x7fdd289e92a0>: Failed to establish a new connection: [Errno 111] Connection refused'))
Waiting for 10 secs for the system to be ready: HTTPConnectionPool(host='localhost', port=8000): Max retries exceeded with url: /sysinfo (Caused by NewConnectionError('<urllib3.connection.HTTPConnection object at 0x7fdd289eab00>: Failed to establish a new connection: [Errno 111] Connection refused'))
Waiting for 10 secs for the system to be ready: HTTPConnectionPool(host='localhost', port=8000): Max retries exceeded with url: /sysinfo (Caused by NewConnectionError('<urllib3.connection.HTTPConnection object at 0x7fdd289e8a90>: Failed to establish a new connection: [Errno 111] Connection refused'))
Waiting for 10 secs for the system to be ready: HTTPConnectionPool(host='localhost', port=8000): Max retries exceeded with url: /sysinfo (Caused by NewConnectionError('<urllib3.connection.HTTPConnection object at 0x7fdd289e92d0>: Failed to establish a new connection: [Errno 111] Connection refused'))
Waiting for 10 secs for the system to be ready: HTTPConnectionPool(host='localhost', port=8000): Max retries exceeded with url: /sysinfo (Caused by NewConnectionError('<urllib3.connection.HTTPConnection object at 0x7fdd289e9b40>: Failed to establish a new connection: [Errno 111] Connection refused'))
Waiting for 10 secs for the system to be ready: HTTPConnectionPool(host='localhost', port=8000): Max retries exceeded with url: /sysinfo (Caused by NewConnectionError('<urllib3.connection.HTTPConnection object at 0x7fdd289ea920>: Failed to establish a new connection: [Errno 111] Connection refused'))
Waiting for 10 secs for the system to be ready: HTTPConnectionPool(host='localhost', port=8000): Max retries exceeded with url: /sysinfo (Caused by NewConnectionError('<urllib3.connection.HTTPConnection object at 0x7fdd289ead40>: Failed to establish a new connection: [Errno 111] Connection refused'))
Waiting for 10 secs for the system to be ready: HTTPConnectionPool(host='localhost', port=8000): Max retries exceeded with url: /sysinfo (Caused by NewConnectionError('<urllib3.connection.HTTPConnection object at 0x7fdd28df3c40>: Failed to establish a new connection: [Errno 111] Connection refused'))
Waiting for 10 secs for the system to be ready: HTTPConnectionPool(host='localhost', port=8000): Max retries exceeded with url: /sysinfo (Caused by NewConnectionError('<urllib3.connection.HTTPConnection object at 0x7fdd289eac20>: Failed to establish a new connection: [Errno 111] Connection refused'))
Waiting for 10 secs for the system to be ready: HTTPConnectionPool(host='localhost', port=8000): Max retries exceeded with url: /sysinfo (Caused by NewConnectionError('<urllib3.connection.HTTPConnection object at 0x7fdd289ea740>: Failed to establish a new connection: [Errno 111] Connection refused'))
Waiting for 10 secs for the system to be ready: HTTPConnectionPool(host='localhost', port=8000): Max retries exceeded with url: /sysinfo (Caused by NewConnectionError('<urllib3.connection.HTTPConnection object at 0x7fdd289e9ed0>: Failed to establish a new connection: [Errno 111] Connection refused'))
Waiting for 10 secs for the system to be ready: HTTPConnectionPool(host='localhost', port=8000): Max retries exceeded with url: /sysinfo (Caused by NewConnectionError('<urllib3.connection.HTTPConnection object at 0x7fdd289e9660>: Failed to establish a new connection: [Errno 111] Connection refused'))
slurmstepd: error: *** JOB 3671896 ON HOST-10-140-60-5 CANCELLED AT 2024-05-13T03:37:44 ***
*** SIGTERM received at time=1715542664 on cpu 41 ***
[failure_signal_handler.cc : 332] RAW: Signal 15 raised at PC=0x7fa4a9791a7d while already in AbslFailureSignalHandler()
*** SIGTERM received at time=1715542664 on cpu 41 ***
PC: @     0x7fa4a9791a7d  (unknown)  syscall
    @     0x7fa4a96b5520       3360  (unknown)
    @     0x7fa3596143d4        208  absl::lts_20230125::WriteSignalMessage()
    @     0x7fa3596144af         80  absl::lts_20230125::AbslFailureSignalHandler()
    @     0x7fa4a96b5520  (unknown)  (unknown)
    @ ... and at least 3 more frames
[2024-05-13 03:37:44,550 E 50336 50336] logging.cc:365: *** SIGTERM received at time=1715542664 on cpu 41 ***
[2024-05-13 03:37:44,550 E 50336 50336] logging.cc:365: PC: @     0x7fa4a9791a7d  (unknown)  syscall
[2024-05-13 03:37:44,550 E 50336 50336] logging.cc:365:     @     0x7fa4a96b5520       3360  (unknown)
[2024-05-13 03:37:44,550 E 50336 50336] logging.cc:365:     @     0x7fa3596143d4        208  absl::lts_20230125::WriteSignalMessage()
[2024-05-13 03:37:44,550 E 50336 50336] logging.cc:365:     @     0x7fa3596144af         80  absl::lts_20230125::AbslFailureSignalHandler()
[2024-05-13 03:37:44,550 E 50336 50336] logging.cc:365:     @     0x7fa4a96b5520  (unknown)  (unknown)
[2024-05-13 03:37:44,550 E 50336 50336] logging.cc:365:     @ ... and at least 3 more frames
PC: @     0x561021fe7f9f  (unknown)  _PyEval_EvalFrameDefault
    @     0x7fa4a96b5520  (unknown)  (unknown)
    @ ... and at least 3 more frames
[2024-05-13 03:37:44,551 E 50336 50336] logging.cc:365: *** SIGTERM received at time=1715542664 on cpu 41 ***
[2024-05-13 03:37:44,551 E 50336 50336] logging.cc:365: PC: @     0x561021fe7f9f  (unknown)  _PyEval_EvalFrameDefault
[2024-05-13 03:37:44,551 E 50336 50336] logging.cc:365:     @     0x7fa4a96b5520  (unknown)  (unknown)
[2024-05-13 03:37:44,551 E 50336 50336] logging.cc:365:     @ ... and at least 3 more frames
